Workbook
Name BHT: 'Precios bases'!$G$285:$G$299
Name BHT: Parametros!$G$288:$G$302
Name CAMPO: #REF!
Name CEX: 'Precios bases'!$D$285:$D$299
Name CEX: Parametros!$D$288:$D$302
Name CRE: Parametros!$J$288:$J$302
Name CREATIVE: 'Precios bases'!$J$285:$J$299
Name CREATIVE: Parametros!$J$288:$J$302
Name Guidelines_1: #REF!
Name Guidelines_1: #REF!
Name Guidelines_2: #REF!,#REF!,#REF!,#REF!
Name Guidelines_2: #REF!,#REF!,#REF!,#REF!
Name Guidelines_2: #REF!,#REF!,#REF!,#REF!
Name Guidelines10: '[1]Auxiliary Sheet'!$AA$2:$AA$11
Name Guidelines10: '[2]Auxiliary Sheet'!$AA$2:$AA$11
Name HEC: 'Precios bases'!$F$285:$F$299
Name HEC: Parametros!$F$288:$F$302
Name Horas: Horas!$E$2:$E$1048576
Name INNO: 'Precios bases'!$C$285:$C$299
Name INNO: Parametros!$C$288:$C$302
Name Metodologia: Horas!$D$2:$D$1048576
Name MSU: 'Precios bases'!$E$285:$E$299
Name MSU: Parametros!$E$288:$E$302
Name N: #REF!,#REF!,#REF!,#REF!
Name N: #REF!,#REF!,#REF!,#REF!
Name OBS: Parametros!$K$288:$K$302
Name OPS: Parametros!$K$288:$K$302
Name PA: 'Precios bases'!$H$285:$H$299
Name PA: Parametros!$H$288:$H$302
Name Record_Detail_Level: Horas!$C$2:$C$1048576
Name SL: Horas!$B$2:$B$1048576
Name UX: 'Precios bases'!$I$285:$I$299
Name UX: Parametros!$I$288:$I$302

Sheet Entradas
C4: Nombre Propuesta/#
C5: Grupo Objetivo
C6: Cliente
C7: Fecha de aprobación estimada
C8: Fecha de campo
C9: Probabilidad de aprobación | D9: Alta
C10: SL | D10: MSU
C11: Metodología SL | D11: MSC005 - U&A
C12: Record Detail | D12: Ops
C13: Categoria /Producto | D13: Otro | E13: =VLOOKUP(D13,Parametros!C243:D272,2,0) -> 0 | F13: =IF(E13>17,"Revisar con el área de cotización, Sara Vergara o Sandra Guecha",IF(E13=2,"Agregar en la descripción del grupo objetivo la hora de inicio de labor en campo",0)) -> 0
C14: Valor proveedor EXTERNO COLOMBIA | G14: Días de campo | H14: No Enc por Locación
C15: Valor proveedor INTERNACIONAL
C16: Metodología de Recolección | D16: Hogares | E16: =VLOOKUP(D16,Parametros!$B$230:$C$239,2,0) -> 0 | F16: TIPO VISITA 1 | G16: Básica - Video | I16: TIPO VISITA 2 | J16: Ninguna | L16: TIPO VISITA 3 | M16: Ninguna
C17: =HYPERLINK("#MuestraTec1!J20","Técnica de Recolección 1: Ir a diligenciar muestra") -> Técnica de Recolección 1: Ir a diligenciar muestra | D17: F2F | E17: =VLOOKUP(D17,Parametros!$F$232:$G$242,2,0) -> 1 | F17: TIPO VISITA 1 | I17: TIPO VISITA 2 | L17: TIPO VISITA 3
C18: =HYPERLINK("#MuestraTec2!J20","Técnica de Recolección 2: Ir a diligenciar muestra") -> Técnica de Recolección 2: Ir a diligenciar muestra | D18: NINGUNA | E18: =VLOOKUP(D18,Parametros!$F$232:$G$242,2,0) -> 0
C19: Base de datos | D19: No requiere | E19: =VLOOKUP(D19,Parametros!E204:F206,2,0) -> 0 | F19: 0 | G19: =IF(E19=1,"Revisar con el área de cotización, Sara Vergara o Sandra Guecha",0) -> 0
C20: Penetración | D20: =VLOOKUP(E20,Parametros!B24:C34,2,0) -> 0.82 | E20: Mas 82% | F20: =IF(D20>54%,"Recuerde siempre revisar la incidencia con el área de costos, Sara Vergara o Sandra Guecha",0) -> Recuerde siempre revisar la incidencia con el área de costos, Sara Vergara o Sandra Guecha
C21: Duracion | D21: =VLOOKUP(E21,Parametros!B15:C22,2,0) -> 20 | E21: 16-20minutos | F21: =IF(D21>31,"Recuerde que un cuestionario más extenso genera costos y tiempos mayores, debe revisarse con el area de cotización",0) -> 0
C22: # Preguntas abiertas
C23: # Preguntas abiertas Multiples
C24: Otros
C25: Top line | D25: No | E25: {=VLOOKUP(D25,+Parametros!$B$218:$C$220,2,0)} -> 0
C26: Datacleaning | D26: =VLOOKUP(D25,Parametros!$B$222:$C$223,2,FALSE) -> Total | E26: =VLOOKUP($D$26,Parametros!$B$203:$C$205,2,0) -> 1
C27: Conversión/generación archivos ASCII y otros | D27: No | E27: {=VLOOKUP(D27,+Parametros!$B$218:$C$220,2,0)} -> 0
C28: Requiere Script para reclutamiento | D28: No | E28: {=VLOOKUP(D28,+Parametros!$B$218:$C$220,2,0)} -> 0
C29: Scripting | D29: Si | E29: {=VLOOKUP(D29,+Parametros!$B$218:$C$220,2,0)} -> 1 | F29: Nuevo
C30: Codificación | D30: No | E30: {=VLOOKUP(D30,+Parametros!$B$218:$C$220,2,0)} -> 0
C31: Procesamiento | D31: Si | E31: =VLOOKUP(D31,Parametros!$B$219:$C$220,2,0) -> 1
C32: # Procesamientos | E32: 1
C33: Requiere proceso Estadistico | D33: No | E33: {=VLOOKUP(D33,+Parametros!$B$218:$C$220,2,0)} -> 0 | F33: =IF(E33>0,"Diligenciar pestaña Tarifario Estadistica",0) -> 0
C34: Valor GMU (Brasil, francia, EEUU, etc.) | D34: 0
C35: Días de Set up | D35: 2 | E35: 4
C36: #Días de campo | D36: 10 | E36: =+'Costos Directos discriminados'!C57 -> 15
C37: Harmoni | D37: No | E37: =VLOOKUP(D37,Parametros!$B$219:$C$220,2,0) -> 0
C38: Graficación | D38: No | E38: =VLOOKUP(D38,Parametros!$B$219:$C$220,2,0) -> 0
C39: Otros costos
C40: Viáticos para Campo
C41: Otros Incentivos
C42: # Pag. Reprografia/ Tarjetas
C43: Número de Olas/rondas | D43: 1 | E43: =IF(D43>1,"Revisar con el área de cotización o Sara Vergara",0) -> 0
...

Sheet Tarifario Estadistica
A1: No. | B1: Categoría de servicio | C1: Análisis/servicios | D1: Explicación del modelo o entregable | E1: Ejemplo de entregable | F1: Total de horas estimadas* | G1: Precio de referencia (2024) | H1: Factor para manejar economía de escala | I1: En cuánto tiempo aproximadamente se entrega uno de los procesos, previo agendamiento. | J1: Número de modelos a realizar (Se debe llenar) | K1: Precio de referencia por X modelos - Ahorro por economía de escala
A2: 1 | B2: Procesos Especiales | C2: Modelo de satisfacción (CX-variable respuesta en escala) | D2: Es un modelo (completo y el mejor modelo) que se entrega en una hoja excel, con una hoja inicial de guía para interpretación. La condición es que todas las variables deben venir en escala que miden el nivel de satisfacción. | F2: 2 | G2: 224910 | H2: 0.6 | I2: Dos días | J2: 0 | K2: =IF(J2=0,0,G2+(J2-1)*ROUND(G2*H2,0)) -> 0 | L2: =IF(J2=0,0,F2+(J2-1)*ROUND(F2*H2,0)) -> 0
A3: 2 | B3: Procesos Especiales | C3: Orden de atributos o Análisis de Drivers (variable respuesta en escala) | D3: Un modelo (completo y el mejor modelo) se entrega en una hoja excel, con una hoja inicial de guía para interpretación. La condición es que todas las variables deben venir en escala. | F3: 3 | G3: 286856 | H3: 0.3 | I3: Dos días | J3: 4 | K3: =IF(J3=0,0,G3+(J3-1)*ROUND(G3*H3,0)) -> 545027 | L3: =IF(J3=0,0,F3+(J3-1)*ROUND(F3*H3,0)) -> 6
A4: 3 | B4: Procesos Especiales | C4: Orden de atributos o Análisis de Drivers (variable respuesta dicotómica) | D4: Un modelo GLM o de machine learning (el mejor modelo), el cual se entrega en una hoja excel, con una hoja inicial de guía para interpretación. Esto ocurre cuando la variable respuesta (Y) es una variable que contiene ceros y unos. | F4: 4 | G4: 449820 | H4: 0.3 | I4: Dos días | J4: 0 | K4: =IF(J4=0,0,G4+(J4-1)*ROUND(G4*H4,0)) -> 0 | L4: =IF(J4=0,0,F4+(J4-1)*ROUND(F4*H4,0)) -> 0
A5: 4 | B5: Procesos Especiales | C5: Random Forest | D5: Es un modelo dentro de los modelos de machine learning, el cual se entrega en una hoja excel, con una hoja inicial de guía para interpretación. | F5: 3.5 | G5: 317829 | H5: 0.3 | I5: Dos días | J5: 0 | K5: =IF(J5=0,0,G5+(J5-1)*ROUND(G5*H5,0)) -> 0 | L5: =IF(J5=0,0,F5+(J5-1)*ROUND(F5*H5,0)) -> 0
A6: 5 | B6: Procesos Especiales | C6: Modelos GLM (variable con respuesta dicotómica) | D6: Un modelo GLM o de machine learning (el mejor modelo), el cual se entrega en una hoja excel, con una hoja inicial de guía para interpretación. Esto ocurre cuando la variable respuesta (Y) es una variable que contiene ceros y unos. | F6: 9 | G6: 759550 | H6: 0.3 | I6: Dos días | J6: 0 | K6: =IF(J6=0,0,G6+(J6-1)*ROUND(G6*H6,0)) -> 0 | L6: =IF(J6=0,0,F6+(J6-1)*ROUND(F6*H6,0)) -> 0
A7: 6 | B7: Procesos Especiales | C7: Modelos de machine learning | D7: Es un modelo de machine learning que aprende de la información existente y predice la información del indicador para los encuestado. Se entrega un documento del modelo y la BDD con la variable predicha. | F7: 30 | G7: 3878740 | H7: 0.3 | I7: Cuatro días | J7: 0 | K7: =IF(J7=0,0,G7+(J7-1)*ROUND(G7*H7,0)) -> 0 | L7: =IF(J7=0,0,F7+(J7-1)*ROUND(F7*H7,0)) -> 0
A8: 7 | B8: Procesos Especiales | C8: Modelos para tasa de no respuesta muy altas | D8: Es un modelo de machine learning que aprende de la información recolectada y predice, con información existente de los no-encuestado, la información faltante. Se entrega un documento del modelo y la BDD con la variable predicha. | F8: 10 | G8: 1023532 | H8: 0.5 | I8: Tres días | J8: 0 | K8: =IF(J8=0,0,G8+(J8-1)*ROUND(G8*H8,0)) -> 0 | L8: =IF(J8=0,0,F8+(J8-1)*ROUND(F8*H8,0)) -> 0
A9: 8 | B9: Procesos Especiales | C9: Modelo de anonimización | D9: Es un modelo de machine learning que anonimiza variables cualitativa o cuantitativas, para la no posible identificación del encuestado, sin afectar los resultados descriptivos. Se entrega un documento del modelo y la BDD con la variable anonimizada. | E9: Y BDD… | F9: 8 | G9: 899640 | H9: 0.5 | I9: Tres días | J9: 0 | K9: =IF(J9=0,0,G9+(J9-1)*ROUND(G9*H9,0)) -> 0 | L9: =IF(J9=0,0,F9+(J9-1)*ROUND(F9*H9,0)) -> 0
A10: 9 | B10: Procesos Especiales | C10: Graphical modelling (INNO-sin magnitud de la relación) | D10: Se entrega un grafo en archivo .html interactivo, que muestra relaciones entre atributos y una variable respuesta en escala o dicotómica. | F10: 2.5 | G10: 356901 | H10: 0.7 | I10: Dos días | J10: 0 | K10: =IF(J10=0,0,G10+(J10-1)*ROUND(G10*H10,0)) -> 0 | L10: =IF(J10=0,0,F10+(J10-1)*ROUND(F10*H10,0)) -> 0
A11: 10 | B11: Procesos Especiales | C11: Graphical modelling (con magnitud de la relación) | D11: Se entrega un grafo en archivo .html interactivo, que muestra relaciones entre atributos y una variable respuesta en escala o dicotómica, en donde se incluye la magnitud de la relación para cada enlace, que representa la fuerza de la relación existente entre los dos atributos. | F11: 3 | G11: 387874 | H11: 0.7 | I11: Dos días | J11: 0 | K11: =IF(J11=0,0,G11+(J11-1)*ROUND(G11*H11,0)) -> 0 | L11: =IF(J11=0,0,F11+(J11-1)*ROUND(F11*H11,0)) -> 0 | M11: 271512 | N11: =+K11-L11-M11 -> -271512 | O11: =+N11*2 -> -543024
A12: 11 | B12: Procesos Especiales | C12: Graphical modelling + Orden de atributos (variable respuesta en escala) | D12: Se entrega un grafo en archivo .html interactivo y un modelo de orden de atributos (la condición es que la variable respuesta debe ser en escala). | F12: 5 | G12: 511766 | H12: 0.7 | I12: Dos días | J12: 4 | K12: =IF(J12=0,0,G12+(J12-1)*ROUND(G12*H12,0)) -> 1586474 | L12: =IF(J12=0,0,F12+(J12-1)*ROUND(F12*H12,0)) -> 17
A13: 12 | B13: Procesos Especiales | C13: Graphical modelling + Orden de atributos (variable respuesta dicotómica) | D13: Se entrega un grafo en archivo .html interactivo y un modelo de orden de atributos (la condición es que la variable respuesta debe ser dicotómica). | F13: 5.5 | G13: 542739 | H13: 0.7 | I13: Dos días | J13: 0 | K13: =IF(J13=0,0,G13+(J13-1)*ROUND(G13*H13,0)) -> 0 | L13: =IF(J13=0,0,F13+(J13-1)*ROUND(F13*H13,0)) -> 0
A14: 13 | B14: Procesos Especiales | C14: Correlaciones/asociaciones | D14: Se entrega en archivo excel con la matrix correlaciones o asociaciones, con las variables señaladas sin apertura. | F14: 1 | G14: 162964 | H14: 0.7 | I14: Dos días | J14: 0 | K14: =IF(J14=0,0,G14+(J14-1)*ROUND(G14*H14,0)) -> 0 | L14: =IF(J14=0,0,F14+(J14-1)*ROUND(F14*H14,0)) -> 0
A15: 14 | B15: Procesos Especiales | C15: Inferencia Estadística (diferencias, pruebas de hipotesis, metas, análisis migratorio) | D15: Se entrega en archivo excel con el resultado de la prueba estadística o inferencia señalada sin apertura. | F15: 4 | G15: 449820 | H15: 0.7 | I15: Dos días | J15: 0 | K15: =IF(J15=0,0,G15+(J15-1)*ROUND(G15*H15,0)) -> 0 | L15: =IF(J15=0,0,F15+(J15-1)*ROUND(F15*H15,0)) -> 0
A16: 15 | B16: Procesos Especiales | C16: Text analytics (CREATIVE-De palabras) | D16: Se entrega dos grafos, uno el original y el otro con su debida partición, las métricas y la identificación de cada palabra con su grupo y número de menciones. | F16: 5 | G16: 511766 | H16: 0.75 | I16: Dos días | J16: 0 | K16: =IF(J16=0,0,G16+(J16-1)*ROUND(G16*H16,0)) -> 0 | L16: =IF(J16=0,0,F16+(J16-1)*ROUND(F16*H16,0)) -> 0
A17: 16 | B17: Procesos Especiales | C17: Text Analytics por LDA ( frases construidas) | D17: Se entrega una clasificación de verbatims, que ayuda a la construcción de frases que hace la SL, luego con las frases se hace un grafo, donde se precisan colores y edición corta de la frase, lo cual se entrega en un archivo .html. | F17: 13 | G17: 1209370 | I17: Una semana | J17: 0 | K17: =IF(J17=0,0,G17+(J17-1)*ROUND(G17*H17,0)) -> 0 | L17: =IF(J17=0,0,F17+(J17-1)*ROUND(F17*H17,0)) -> 0
A18: 17 | B18: Procesos Especiales | C18: Text analytics con segmentación y depurado de palabras | D18: Se entrega máximo tres grafos, el original con su debida partición y máximo dos depuraciones de palabras, las métricas y la identificación de cada palabra con su grupo y número de menciones. | F18: 8 | G18: 899640 | H18: 0.75 | I18: Tres días | J18: 0 | K18: =IF(J18=0,0,G18+(J18-1)*ROUND(G18*H18,0)) -> 0 | L18: =IF(J18=0,0,F18+(J18-1)*ROUND(F18*H18,0)) -> 0
A19: 18 | B19: Procesos Especiales | C19: Text analytics depurado de marcas | D19: Se entrega máximo tres grafos con máximo cuatro marcas, el original con su debida partición de marcas y máximo dos depuraciones de palabras de las marcas, las métricas y la identificación de cada palabra con su grupo y número de menciones. | F19: 11 | G19: 1085478 | H19: 0.75 | I19: Tres días | J19: 0 | K19: =IF(J19=0,0,G19+(J19-1)*ROUND(G19*H19,0)) -> 0 | L19: =IF(J19=0,0,F19+(J19-1)*ROUND(F19*H19,0)) -> 0
A20: 19 | B20: Procesos Especiales | C20: Text analytics con segmentación y asociando imágenes | D20: Es un archivo .html con un grafo, un archivo excel con identificación para cada registro el grupo al que pertenece y la identificación de las imágenes más frecuentes en cada grupo. | F20: 11 | G20: 1085478 | I20: Tres días | J20: 0 | K20: =IF(J20=0,0,G20+(J20-1)*ROUND(G20*H20,0)) -> 0 | L20: =IF(J20=0,0,F20+(J20-1)*ROUND(F20*H20,0)) -> 0
A21: 20 | B21: Procesos Especiales | C21: Penalty Analysis | D21: Se entregan dos archivos .html con las penalidades y otro con los porcentajes de cada grupo por atributos, estos mismos archivos se entregan en excel. | F21: 2 | G21: 224910 | H21: 0.5 | I21: Un día | J21: 0 | K21: =IF(J21=0,0,G21+(J21-1)*ROUND(G21*H21,0)) -> 0 | L21: =IF(J21=0,0,F21+(J21-1)*ROUND(F21*H21,0)) -> 0
A22: 21 | B22: Procesos Especiales | C22: Reglas de asociación | D22: Ante la pregunta de los productos que compró, se pueden identificar productos complementarios y sustitutos, los cuales son identificados en este análisis que se entrega en excel, con el calculo de lift. | F22: 3 | G22: 387874 | H22: 0.5 | I22: Dos días | J22: 0 | K22: =IF(J22=0,0,G22+(J22-1)*ROUND(G22*H22,0)) -> 0 | L22: =IF(J22=0,0,F22+(J22-1)*ROUND(F22*H22,0)) -> 0
A23: 22 | B23: Procesos Especiales | C23: Indicadores (ACP) | D23: El indicador se entrega en una hoja excel, con el peso de cada una de las variables involucradas en el análisis, su matrix de correlaciones, el calculo del indicador en una apertura requerida y el cálculo del indicador en cada uno de los registros del estudio. | F23: 4 | G23: 449820 | H23: 0.7 | I23: Dos días | J23: 0 | K23: =IF(J23=0,0,G23+(J23-1)*ROUND(G23*H23,0)) -> 0 | L23: =IF(J23=0,0,F23+(J23-1)*ROUND(F23*H23,0)) -> 0
A24: 23 | B24: Procesos Especiales | C24: Análisis factorial (redución o agrupamiento de variables) | D24: Se entrega el cluster del agrupamiento de variables, junto con la matrix de similitudes, el dendograma y el peso de cada variables a los factores creaados en excel. | F24: 5 | G24: 612784 | H24: 0.7 | I24: Tres días | J24: 0 | K24: =IF(J24=0,0,G24+(J24-1)*ROUND(G24*H24,0)) -> 0 | L24: =IF(J24=0,0,F24+(J24-1)*ROUND(F24*H24,0)) -> 0
A25: 24 | B25: Procesos Especiales | C25: Residuales ajustados | D25: Es una matrix de distancias estándarizadas de marcas vs atributos, donde se visualiza la asociaciones significativas tanto en la matrix cómo gráficamente, el archivo se entrega en excel. | F25: 3 | G25: 286856 | H25: 0.7 | I25: Dos días | J25: 0 | K25: =IF(J25=0,0,G25+(J25-1)*ROUND(G25*H25,0)) -> 0 | L25: =IF(J25=0,0,F25+(J25-1)*ROUND(F25*H25,0)) -> 0
A26: 25 | B26: Procesos Especiales | C26: Mapa de correspondencia | D26: Se entrega un mapa y dendograma en una hoja excel, con las coordenadas de cada punto, las proyecciones de los casos ilustrativos (cuando hay bases muy pequeñas) y las agrupaciones sombreadas a partir de los análisis de dendogramas. | F26: 4.5 | G26: 480793 | H26: 0.7 | I26: Dos días | J26: 0 | K26: =IF(J26=0,0,G26+(J26-1)*ROUND(G26*H26,0)) -> 0 | L26: =IF(J26=0,0,F26+(J26-1)*ROUND(F26*H26,0)) -> 0
A27: 26 | B27: Procesos Especiales | C27: Mapa de correspondencia+residuales | D27: Se entrega el mapa de correspondencia y la matrix de residuales, para evidenciar no solo las agrupaciones sombreadas sino las relaciones más significativas entre atributos y marcas. | F27: 5.5 | G27: 542739 | H27: 0.7 | I27: Tres días | J27: 0 | K27: =IF(J27=0,0,G27+(J27-1)*ROUND(G27*H27,0)) -> 0 | L27: =IF(J27=0,0,F27+(J27-1)*ROUND(F27*H27,0)) -> 0
A28: 27 | B28: Procesos Especiales | C28: Equity actitudinal con funnel | D28: Es un archivo excel con el cálculo del AE para cada registro y marca, además de otra hoja donde se encuentra el consolidado de los resutlados del equity por marca y la clasificación cualitativa de este. | F28: 3 | G28: 286856 | H28: 0.8 | I28: Dos días | J28: 0 | K28: =IF(J28=0,0,G28+(J28-1)*ROUND(G28*H28,0)) -> 0 | L28: =IF(J28=0,0,F28+(J28-1)*ROUND(F28*H28,0)) -> 0
A29: 28 | B29: Procesos Especiales | C29: Segmentación o perfilamiento (Análisis de Cluster) | D29: Tres opciones de perfiles con el cruce de cada una de las variables del perfilamiento y el peso de cada perfil, además de los residuales. | F29: 14 | G29: 1271316 | H29: 0.9 | I29: Tres días | J29: 0 | K29: =IF(J29=0,0,G29+(J29-1)*ROUND(G29*H29,0)) -> 0 | L29: =IF(J29=0,0,F29+(J29-1)*ROUND(F29*H29,0)) -> 0
A30: 29 | B30: Procesos Especiales | C30: Segmentación cruzada | D30: Se entregan dos segmentaciones una usualmente de la muestra de personas y la otra segmentación de ocasiones o necesidades, las cuales se cruzan para identificar los mejores segmentos. | F30: 28 | G30: 2542632 | I30: Siete días | J30: 0 | K30: =IF(J30=0,0,G30+(J30-1)*ROUND(G30*H30,0)) -> 0 | L30: =IF(J30=0,0,F30+(J30-1)*ROUND(F30*H30,0)) -> 0
A31: 30 | B31: Procesos Especiales | C31: Segmentación (Análisis de clúster) + Algoritmo (typing tool) | D31: Tres opciones de segmentación con el cruce de cada una de las variables de la segmentación, el peso de cada perfil y un algoritmo en excel o shiny para una clasificación a posteriori. | F31: 30 | G31: 2666524 | H31: 0.9 | I31: Dos semanas | J31: 0 | K31: =IF(J31=0,0,G31+(J31-1)*ROUND(G31*H31,0)) -> 0 | L31: =IF(J31=0,0,F31+(J31-1)*ROUND(F31*H31,0)) -> 0
A32: 31 | B32: Procesos Especiales | C32: Turf | D32: Se entrega un gráfico en excel, con el ordenamiento y contribución de cada medio, canal o ente de evaluación. | F32: 2.5 | G32: 255883 | H32: 0.4 | I32: Dos días | J32: 0 | K32: =IF(J32=0,0,G32+(J32-1)*ROUND(G32*H32,0)) -> 0 | L32: =IF(J32=0,0,F32+(J32-1)*ROUND(F32*H32,0)) -> 0
A33: 32 | B33: Procesos Especiales | C33: Odds ration | D33: Se entrega en una hoja excel las frecuencias, el odd para las variables señaladas, y un ejemplo de la interpretación. | F33: 2 | G33: 224910 | H33: 0.5 | I33: Dos días | J33: 0 | K33: =IF(J33=0,0,G33+(J33-1)*ROUND(G33*H33,0)) -> 0 | L33: =IF(J33=0,0,F33+(J33-1)*ROUND(F33*H33,0)) -> 0
A34: 33 | B34: Procesos Especiales | C34: Indicadores simples | D34: Se entrega una tabla en excel con el indicador calculado. | F34: 2.5 | G34: 255883 | H34: 0.9 | I34: Dos días | J34: 0 | K34: =IF(J34=0,0,G34+(J34-1)*ROUND(G34*H34,0)) -> 0 | L34: =IF(J34=0,0,F34+(J34-1)*ROUND(F34*H34,0)) -> 0
A35: 34 | B35: Procesos Especiales | C35: Penalty & Rewards | D35: Se entrega un archivo excel con los pesos de los factores y atributos, para un segmento, además de las penalidades y rewards. | F35: 5 | G35: 511766 | H35: 0.6 | I35: Dos días | J35: 0 | K35: =IF(J35=0,0,G35+(J35-1)*ROUND(G35*H35,0)) -> 0 | L35: =IF(J35=0,0,F35+(J35-1)*ROUND(F35*H35,0)) -> 0
A36: 35 | B36: Procesos Especiales | C36: Aporte entre marcas (similar a Brand Halo) | D36: Es un archivo en excel que muestra el aporte de cada atributo o submarca a una marca principal, junto con las diferencias significativas de los resultados. | F36: 4 | G36: 449820 | H36: 0.3 | I36: Dos días | J36: 0 | K36: =IF(J36=0,0,G36+(J36-1)*ROUND(G36*H36,0)) -> 0 | L36: =IF(J36=0,0,F36+(J36-1)*ROUND(F36*H36,0)) -> 0
A37: 36 | B37: Procesos Especiales | C37: Aplicación de algoritmo de segmentación | D37: Previo entrega de un algoritmo de segmentación, este se aplica a una nueva BDD y se entrega en excel el cluster de cada registro. | F37: 3 | G37: 286856 | H37: 0.75 | I37: Un día | J37: 0 | K37: =IF(J37=0,0,G37+(J37-1)*ROUND(G37*H37,0)) -> 0 | L37: =IF(J37=0,0,F37+(J37-1)*ROUND(F37*H37,0)) -> 0
A38: 37 | B38: Procesos Especiales | C38: Análisis chaid (Árboles de clasificación) | D38: Un árbol de clasificiación con su debida documentación que presenta el análisis e interpretación. | F38: 3.5 | G38: 418847 | H38: 0.75 | I38: Dos días | J38: 0 | K38: =IF(J38=0,0,G38+(J38-1)*ROUND(G38*H38,0)) -> 0 | L38: =IF(J38=0,0,F38+(J38-1)*ROUND(F38*H38,0)) -> 0
A39: 38 | B39: Procesos Especiales | C39: Análisis chaid (CX-Árboles de clasificación) | D39: Un árbol de clasificiación, para una variable categórica como NPS o Satisfacción con su debida interpretación, se entrega en un archivo excel. | F39: 2.5 | G39: 255883 | H39: 0.75 | I39: Dos días | J39: 0 | K39: =IF(J39=0,0,G39+(J39-1)*ROUND(G39*H39,0)) -> 0 | L39: =IF(J39=0,0,F39+(J39-1)*ROUND(F39*H39,0)) -> 0
A40: 39 | B40: Procesos Especiales | C40: Análisis de causalidad con redes bayesianas (similar a IBN) | D40: Se entrega un archivo .html con un grafo acíclico dirigido, basado en redes bayesinas que permiten encontrar la causalidad de la relación entre dos atributos (flechas). | F40: 13 | G40: 1209370 | H40: 0.5 | I40: Una semana | J40: 0 | K40: =IF(J40=0,0,G40+(J40-1)*ROUND(G40*H40,0)) -> 0 | L40: =IF(J40=0,0,F40+(J40-1)*ROUND(F40*H40,0)) -> 0
...

Sheet Tarifario Estadistica2
A1: No. | B1: Categoría de servicio | C1: Análisis/servicios | D1: Explicación del modelo o entregable | E1: Ejemplo de entregable | F1: Total de horas estimadas* | G1: Precio de referencia (2024) | H1: Factor para manejar economía de escala | I1: En cuánto tiempo aproximadamente se entrega uno de los procesos, previo agendamiento. | J1: Número de modelos a realizar (Se debe llenar) | K1: Precio de referencia por X modelos - Ahorro por economía de escala
A2: 1 | B2: Procesos Especiales | C2: Modelo de satisfacción (CX-variable respuesta en escala) | D2: Es un modelo (completo y el mejor modelo) que se entrega en una hoja excel, con una hoja inicial de guía para interpretación. La condición es que todas las variables deben venir en escala que miden el nivel de satisfacción. | F2: 2 | G2: 224910 | H2: 0.6 | I2: Dos días | J2: 0 | K2: =IF(J2=0,0,G2+(J2-1)*ROUND(G2*H2,0)) -> 0 | L2: =IF(J2=0,0,F2+(J2-1)*ROUND(F2*H2,0)) -> 0
A3: 2 | B3: Procesos Especiales | C3: Orden de atributos o Análisis de Drivers (variable respuesta en escala) | D3: Un modelo (completo y el mejor modelo) se entrega en una hoja excel, con una hoja inicial de guía para interpretación. La condición es que todas las variables deben venir en escala. | F3: 3 | G3: 286856 | H3: 0.3 | I3: Dos días | J3: 0 | K3: =IF(J3=0,0,G3+(J3-1)*ROUND(G3*H3,0)) -> 0 | L3: =IF(J3=0,0,F3+(J3-1)*ROUND(F3*H3,0)) -> 0
A4: 3 | B4: Procesos Especiales | C4: Orden de atributos o Análisis de Drivers (variable respuesta dicotómica) | D4: Un modelo GLM o de machine learning (el mejor modelo), el cual se entrega en una hoja excel, con una hoja inicial de guía para interpretación. Esto ocurre cuando la variable respuesta (Y) es una variable que contiene ceros y unos. | F4: 4 | G4: 449820 | H4: 0.3 | I4: Dos días | J4: 0 | K4: =IF(J4=0,0,G4+(J4-1)*ROUND(G4*H4,0)) -> 0 | L4: =IF(J4=0,0,F4+(J4-1)*ROUND(F4*H4,0)) -> 0
A5: 4 | B5: Procesos Especiales | C5: Random Forest | D5: Es un modelo dentro de los modelos de machine learning, el cual se entrega en una hoja excel, con una hoja inicial de guía para interpretación. | F5: 3.5 | G5: 317829 | H5: 0.3 | I5: Dos días | J5: 0 | K5: =IF(J5=0,0,G5+(J5-1)*ROUND(G5*H5,0)) -> 0 | L5: =IF(J5=0,0,F5+(J5-1)*ROUND(F5*H5,0)) -> 0
A6: 5 | B6: Procesos Especiales | C6: Modelos GLM (variable con respuesta dicotómica) | D6: Un modelo GLM o de machine learning (el mejor modelo), el cual se entrega en una hoja excel, con una hoja inicial de guía para interpretación. Esto ocurre cuando la variable respuesta (Y) es una variable que contiene ceros y unos. | F6: 9 | G6: 759550 | H6: 0.3 | I6: Dos días | J6: 0 | K6: =IF(J6=0,0,G6+(J6-1)*ROUND(G6*H6,0)) -> 0 | L6: =IF(J6=0,0,F6+(J6-1)*ROUND(F6*H6,0)) -> 0
A7: 6 | B7: Procesos Especiales | C7: Modelos de machine learning | D7: Es un modelo de machine learning que aprende de la información existente y predice la información del indicador para los encuestado. Se entrega un documento del modelo y la BDD con la variable predicha. | F7: 30 | G7: 3878740 | H7: 0.3 | I7: Cuatro días | J7: 0 | K7: =IF(J7=0,0,G7+(J7-1)*ROUND(G7*H7,0)) -> 0 | L7: =IF(J7=0,0,F7+(J7-1)*ROUND(F7*H7,0)) -> 0
A8: 7 | B8: Procesos Especiales | C8: Modelos para tasa de no respuesta muy altas | D8: Es un modelo de machine learning que aprende de la información recolectada y predice, con información existente de los no-encuestado, la información faltante. Se entrega un documento del modelo y la BDD con la variable predicha. | F8: 10 | G8: 1023532 | H8: 0.5 | I8: Tres días | J8: 0 | K8: =IF(J8=0,0,G8+(J8-1)*ROUND(G8*H8,0)) -> 0 | L8: =IF(J8=0,0,F8+(J8-1)*ROUND(F8*H8,0)) -> 0
A9: 8 | B9: Procesos Especiales | C9: Modelo de anonimización | D9: Es un modelo de machine learning que anonimiza variables cualitativa o cuantitativas, para la no posible identificación del encuestado, sin afectar los resultados descriptivos. Se entrega un documento del modelo y la BDD con la variable anonimizada. | E9: Y BDD… | F9: 8 | G9: 899640 | H9: 0.5 | I9: Tres días | J9: 0 | K9: =IF(J9=0,0,G9+(J9-1)*ROUND(G9*H9,0)) -> 0 | L9: =IF(J9=0,0,F9+(J9-1)*ROUND(F9*H9,0)) -> 0
A10: 9 | B10: Procesos Especiales | C10: Graphical modelling (INNO-sin magnitud de la relación) | D10: Se entrega un grafo en archivo .html interactivo, que muestra relaciones entre atributos y una variable respuesta en escala o dicotómica. | F10: 2.5 | G10: 356901 | H10: 0.7 | I10: Dos días | J10: 0 | K10: =IF(J10=0,0,G10+(J10-1)*ROUND(G10*H10,0)) -> 0 | L10: =IF(J10=0,0,F10+(J10-1)*ROUND(F10*H10,0)) -> 0
A11: 10 | B11: Procesos Especiales | C11: Graphical modelling (con magnitud de la relación) | D11: Se entrega un grafo en archivo .html interactivo, que muestra relaciones entre atributos y una variable respuesta en escala o dicotómica, en donde se incluye la magnitud de la relación para cada enlace, que representa la fuerza de la relación existente entre los dos atributos. | F11: 3 | G11: 387874 | H11: 0.7 | I11: Dos días | J11: 0 | K11: =IF(J11=0,0,G11+(J11-1)*ROUND(G11*H11,0)) -> 0 | L11: =IF(J11=0,0,F11+(J11-1)*ROUND(F11*H11,0)) -> 0 | M11: 271512 | N11: =+K11-L11-M11 -> -271512 | O11: =+N11*2 -> -543024
A12: 11 | B12: Procesos Especiales | C12: Graphical modelling + Orden de atributos (variable respuesta en escala) | D12: Se entrega un grafo en archivo .html interactivo y un modelo de orden de atributos (la condición es que la variable respuesta debe ser en escala). | F12: 5 | G12: 511766 | H12: 0.7 | I12: Dos días | J12: 0 | K12: =IF(J12=0,0,G12+(J12-1)*ROUND(G12*H12,0)) -> 0 | L12: =IF(J12=0,0,F12+(J12-1)*ROUND(F12*H12,0)) -> 0
A13: 12 | B13: Procesos Especiales | C13: Graphical modelling + Orden de atributos (variable respuesta dicotómica) | D13: Se entrega un grafo en archivo .html interactivo y un modelo de orden de atributos (la condición es que la variable respuesta debe ser dicotómica). | F13: 5.5 | G13: 542739 | H13: 0.7 | I13: Dos días | J13: 0 | K13: =IF(J13=0,0,G13+(J13-1)*ROUND(G13*H13,0)) -> 0 | L13: =IF(J13=0,0,F13+(J13-1)*ROUND(F13*H13,0)) -> 0
A14: 13 | B14: Procesos Especiales | C14: Correlaciones/asociaciones | D14: Se entrega en archivo excel con la matrix correlaciones o asociaciones, con las variables señaladas sin apertura. | F14: 1 | G14: 162964 | H14: 0.7 | I14: Dos días | J14: 0 | K14: =IF(J14=0,0,G14+(J14-1)*ROUND(G14*H14,0)) -> 0 | L14: =IF(J14=0,0,F14+(J14-1)*ROUND(F14*H14,0)) -> 0
A15: 14 | B15: Procesos Especiales | C15: Inferencia Estadística (diferencias, pruebas de hipotesis, metas, análisis migratorio) | D15: Se entrega en archivo excel con el resultado de la prueba estadística o inferencia señalada sin apertura. | F15: 4 | G15: 449820 | H15: 0.7 | I15: Dos días | J15: 0 | K15: =IF(J15=0,0,G15+(J15-1)*ROUND(G15*H15,0)) -> 0 | L15: =IF(J15=0,0,F15+(J15-1)*ROUND(F15*H15,0)) -> 0
A16: 15 | B16: Procesos Especiales | C16: Text analytics (CREATIVE-De palabras) | D16: Se entrega dos grafos, uno el original y el otro con su debida partición, las métricas y la identificación de cada palabra con su grupo y número de menciones. | F16: 5 | G16: 511766 | H16: 0.75 | I16: Dos días | J16: 0 | K16: =IF(J16=0,0,G16+(J16-1)*ROUND(G16*H16,0)) -> 0 | L16: =IF(J16=0,0,F16+(J16-1)*ROUND(F16*H16,0)) -> 0
A17: 16 | B17: Procesos Especiales | C17: Text Analytics por LDA ( frases construidas) | D17: Se entrega una clasificación de verbatims, que ayuda a la construcción de frases que hace la SL, luego con las frases se hace un grafo, donde se precisan colores y edición corta de la frase, lo cual se entrega en un archivo .html. | F17: 13 | G17: 1209370 | I17: Una semana | J17: 0 | K17: =IF(J17=0,0,G17+(J17-1)*ROUND(G17*H17,0)) -> 0 | L17: =IF(J17=0,0,F17+(J17-1)*ROUND(F17*H17,0)) -> 0
A18: 17 | B18: Procesos Especiales | C18: Text analytics con segmentación y depurado de palabras | D18: Se entrega máximo tres grafos, el original con su debida partición y máximo dos depuraciones de palabras, las métricas y la identificación de cada palabra con su grupo y número de menciones. | F18: 8 | G18: 899640 | H18: 0.75 | I18: Tres días | J18: 0 | K18: =IF(J18=0,0,G18+(J18-1)*ROUND(G18*H18,0)) -> 0 | L18: =IF(J18=0,0,F18+(J18-1)*ROUND(F18*H18,0)) -> 0
A19: 18 | B19: Procesos Especiales | C19: Text analytics depurado de marcas | D19: Se entrega máximo tres grafos con máximo cuatro marcas, el original con su debida partición de marcas y máximo dos depuraciones de palabras de las marcas, las métricas y la identificación de cada palabra con su grupo y número de menciones. | F19: 11 | G19: 1085478 | H19: 0.75 | I19: Tres días | J19: 0 | K19: =IF(J19=0,0,G19+(J19-1)*ROUND(G19*H19,0)) -> 0 | L19: =IF(J19=0,0,F19+(J19-1)*ROUND(F19*H19,0)) -> 0
A20: 19 | B20: Procesos Especiales | C20: Text analytics con segmentación y asociando imágenes | D20: Es un archivo .html con un grafo, un archivo excel con identificación para cada registro el grupo al que pertenece y la identificación de las imágenes más frecuentes en cada grupo. | F20: 11 | G20: 1085478 | I20: Tres días | J20: 0 | K20: =IF(J20=0,0,G20+(J20-1)*ROUND(G20*H20,0)) -> 0 | L20: =IF(J20=0,0,F20+(J20-1)*ROUND(F20*H20,0)) -> 0
A21: 20 | B21: Procesos Especiales | C21: Penalty Analysis | D21: Se entregan dos archivos .html con las penalidades y otro con los porcentajes de cada grupo por atributos, estos mismos archivos se entregan en excel. | F21: 2 | G21: 224910 | H21: 0.5 | I21: Un día | J21: 0 | K21: =IF(J21=0,0,G21+(J21-1)*ROUND(G21*H21,0)) -> 0 | L21: =IF(J21=0,0,F21+(J21-1)*ROUND(F21*H21,0)) -> 0
A22: 21 | B22: Procesos Especiales | C22: Reglas de asociación | D22: Ante la pregunta de los productos que compró, se pueden identificar productos complementarios y sustitutos, los cuales son identificados en este análisis que se entrega en excel, con el calculo de lift. | F22: 3 | G22: 387874 | H22: 0.5 | I22: Dos días | J22: 0 | K22: =IF(J22=0,0,G22+(J22-1)*ROUND(G22*H22,0)) -> 0 | L22: =IF(J22=0,0,F22+(J22-1)*ROUND(F22*H22,0)) -> 0
A23: 22 | B23: Procesos Especiales | C23: Indicadores (ACP) | D23: El indicador se entrega en una hoja excel, con el peso de cada una de las variables involucradas en el análisis, su matrix de correlaciones, el calculo del indicador en una apertura requerida y el cálculo del indicador en cada uno de los registros del estudio. | F23: 4 | G23: 449820 | H23: 0.7 | I23: Dos días | J23: 0 | K23: =IF(J23=0,0,G23+(J23-1)*ROUND(G23*H23,0)) -> 0 | L23: =IF(J23=0,0,F23+(J23-1)*ROUND(F23*H23,0)) -> 0
A24: 23 | B24: Procesos Especiales | C24: Análisis factorial (redución o agrupamiento de variables) | D24: Se entrega el cluster del agrupamiento de variables, junto con la matrix de similitudes, el dendograma y el peso de cada variables a los factores creaados en excel. | F24: 5 | G24: 612784 | H24: 0.7 | I24: Tres días | J24: 0 | K24: =IF(J24=0,0,G24+(J24-1)*ROUND(G24*H24,0)) -> 0 | L24: =IF(J24=0,0,F24+(J24-1)*ROUND(F24*H24,0)) -> 0
A25: 24 | B25: Procesos Especiales | C25: Residuales ajustados | D25: Es una matrix de distancias estándarizadas de marcas vs atributos, donde se visualiza la asociaciones significativas tanto en la matrix cómo gráficamente, el archivo se entrega en excel. | F25: 3 | G25: 286856 | H25: 0.7 | I25: Dos días | J25: 0 | K25: =IF(J25=0,0,G25+(J25-1)*ROUND(G25*H25,0)) -> 0 | L25: =IF(J25=0,0,F25+(J25-1)*ROUND(F25*H25,0)) -> 0
A26: 25 | B26: Procesos Especiales | C26: Mapa de correspondencia | D26: Se entrega un mapa y dendograma en una hoja excel, con las coordenadas de cada punto, las proyecciones de los casos ilustrativos (cuando hay bases muy pequeñas) y las agrupaciones sombreadas a partir de los análisis de dendogramas. | F26: 4.5 | G26: 480793 | H26: 0.7 | I26: Dos días | J26: 0 | K26: =IF(J26=0,0,G26+(J26-1)*ROUND(G26*H26,0)) -> 0 | L26: =IF(J26=0,0,F26+(J26-1)*ROUND(F26*H26,0)) -> 0
A27: 26 | B27: Procesos Especiales | C27: Mapa de correspondencia+residuales | D27: Se entrega el mapa de correspondencia y la matrix de residuales, para evidenciar no solo las agrupaciones sombreadas sino las relaciones más significativas entre atributos y marcas. | F27: 5.5 | G27: 542739 | H27: 0.7 | I27: Tres días | J27: 0 | K27: =IF(J27=0,0,G27+(J27-1)*ROUND(G27*H27,0)) -> 0 | L27: =IF(J27=0,0,F27+(J27-1)*ROUND(F27*H27,0)) -> 0
A28: 27 | B28: Procesos Especiales | C28: Equity actitudinal con funnel | D28: Es un archivo excel con el cálculo del AE para cada registro y marca, además de otra hoja donde se encuentra el consolidado de los resutlados del equity por marca y la clasificación cualitativa de este. | F28: 3 | G28: 286856 | H28: 0.8 | I28: Dos días | J28: 0 | K28: =IF(J28=0,0,G28+(J28-1)*ROUND(G28*H28,0)) -> 0 | L28: =IF(J28=0,0,F28+(J28-1)*ROUND(F28*H28,0)) -> 0
A29: 28 | B29: Procesos Especiales | C29: Segmentación o perfilamiento (Análisis de Cluster) | D29: Tres opciones de perfiles con el cruce de cada una de las variables del perfilamiento y el peso de cada perfil, además de los residuales. | F29: 14 | G29: 1271316 | H29: 0.9 | I29: Tres días | J29: 0 | K29: =IF(J29=0,0,G29+(J29-1)*ROUND(G29*H29,0)) -> 0 | L29: =IF(J29=0,0,F29+(J29-1)*ROUND(F29*H29,0)) -> 0
A30: 29 | B30: Procesos Especiales | C30: Segmentación cruzada | D30: Se entregan dos segmentaciones una usualmente de la muestra de personas y la otra segmentación de ocasiones o necesidades, las cuales se cruzan para identificar los mejores segmentos. | F30: 28 | G30: 2542632 | I30: Siete días | J30: 0 | K30: =IF(J30=0,0,G30+(J30-1)*ROUND(G30*H30,0)) -> 0 | L30: =IF(J30=0,0,F30+(J30-1)*ROUND(F30*H30,0)) -> 0
A31: 30 | B31: Procesos Especiales | C31: Segmentación (Análisis de clúster) + Algoritmo (typing tool) | D31: Tres opciones de segmentación con el cruce de cada una de las variables de la segmentación, el peso de cada perfil y un algoritmo en excel o shiny para una clasificación a posteriori. | F31: 30 | G31: 2666524 | H31: 0.9 | I31: Dos semanas | J31: 0 | K31: =IF(J31=0,0,G31+(J31-1)*ROUND(G31*H31,0)) -> 0 | L31: =IF(J31=0,0,F31+(J31-1)*ROUND(F31*H31,0)) -> 0
A32: 31 | B32: Procesos Especiales | C32: Turf | D32: Se entrega un gráfico en excel, con el ordenamiento y contribución de cada medio, canal o ente de evaluación. | F32: 2.5 | G32: 255883 | H32: 0.4 | I32: Dos días | J32: 0 | K32: =IF(J32=0,0,G32+(J32-1)*ROUND(G32*H32,0)) -> 0 | L32: =IF(J32=0,0,F32+(J32-1)*ROUND(F32*H32,0)) -> 0
A33: 32 | B33: Procesos Especiales | C33: Odds ration | D33: Se entrega en una hoja excel las frecuencias, el odd para las variables señaladas, y un ejemplo de la interpretación. | F33: 2 | G33: 224910 | H33: 0.5 | I33: Dos días | J33: 0 | K33: =IF(J33=0,0,G33+(J33-1)*ROUND(G33*H33,0)) -> 0 | L33: =IF(J33=0,0,F33+(J33-1)*ROUND(F33*H33,0)) -> 0
A34: 33 | B34: Procesos Especiales | C34: Indicadores simples | D34: Se entrega una tabla en excel con el indicador calculado. | F34: 2.5 | G34: 255883 | H34: 0.9 | I34: Dos días | J34: 0 | K34: =IF(J34=0,0,G34+(J34-1)*ROUND(G34*H34,0)) -> 0 | L34: =IF(J34=0,0,F34+(J34-1)*ROUND(F34*H34,0)) -> 0
A35: 34 | B35: Procesos Especiales | C35: Penalty & Rewards | D35: Se entrega un archivo excel con los pesos de los factores y atributos, para un segmento, además de las penalidades y rewards. | F35: 5 | G35: 511766 | H35: 0.6 | I35: Dos días | J35: 0 | K35: =IF(J35=0,0,G35+(J35-1)*ROUND(G35*H35,0)) -> 0 | L35: =IF(J35=0,0,F35+(J35-1)*ROUND(F35*H35,0)) -> 0
A36: 35 | B36: Procesos Especiales | C36: Aporte entre marcas (similar a Brand Halo) | D36: Es un archivo en excel que muestra el aporte de cada atributo o submarca a una marca principal, junto con las diferencias significativas de los resultados. | F36: 4 | G36: 449820 | H36: 0.3 | I36: Dos días | J36: 0 | K36: =IF(J36=0,0,G36+(J36-1)*ROUND(G36*H36,0)) -> 0 | L36: =IF(J36=0,0,F36+(J36-1)*ROUND(F36*H36,0)) -> 0
A37: 36 | B37: Procesos Especiales | C37: Aplicación de algoritmo de segmentación | D37: Previo entrega de un algoritmo de segmentación, este se aplica a una nueva BDD y se entrega en excel el cluster de cada registro. | F37: 3 | G37: 286856 | H37: 0.75 | I37: Un día | J37: 0 | K37: =IF(J37=0,0,G37+(J37-1)*ROUND(G37*H37,0)) -> 0 | L37: =IF(J37=0,0,F37+(J37-1)*ROUND(F37*H37,0)) -> 0
A38: 37 | B38: Procesos Especiales | C38: Análisis chaid (Árboles de clasificación) | D38: Un árbol de clasificiación con su debida documentación que presenta el análisis e interpretación. | F38: 3.5 | G38: 418847 | H38: 0.75 | I38: Dos días | J38: 0 | K38: =IF(J38=0,0,G38+(J38-1)*ROUND(G38*H38,0)) -> 0 | L38: =IF(J38=0,0,F38+(J38-1)*ROUND(F38*H38,0)) -> 0
A39: 38 | B39: Procesos Especiales | C39: Análisis chaid (CX-Árboles de clasificación) | D39: Un árbol de clasificiación, para una variable categórica como NPS o Satisfacción con su debida interpretación, se entrega en un archivo excel. | F39: 2.5 | G39: 255883 | H39: 0.75 | I39: Dos días | J39: 0 | K39: =IF(J39=0,0,G39+(J39-1)*ROUND(G39*H39,0)) -> 0 | L39: =IF(J39=0,0,F39+(J39-1)*ROUND(F39*H39,0)) -> 0
A40: 39 | B40: Procesos Especiales | C40: Análisis de causalidad con redes bayesianas (similar a IBN) | D40: Se entrega un archivo .html con un grafo acíclico dirigido, basado en redes bayesinas que permiten encontrar la causalidad de la relación entre dos atributos (flechas). | F40: 13 | G40: 1209370 | H40: 0.5 | I40: Una semana | J40: 0 | K40: =IF(J40=0,0,G40+(J40-1)*ROUND(G40*H40,0)) -> 0 | L40: =IF(J40=0,0,F40+(J40-1)*ROUND(F40*H40,0)) -> 0
...

Sheet MuestraTec1
C2: NSE 1 | D2: NSE 2 | E2: NSE 3 | F2: NSE 4 | G2: NSE 5 | H2: NSE 6 | I2: Total
B3: Bogotá | C3: 175822 | D3: 772989 | E3: 808409 | F3: 325667 | G3: 106394 | H3: 83335 | I3: =SUM(C3:H3) -> 2272616
B4: Barranquilla | C4: 120736 | D4: 72430 | E4: 82028 | F4: 48172 | G4: 17448 | H4: 13225 | I4: =SUM(C4:H4) -> 354039
B5: Medellín | C5: 135532 | D5: 319438 | E5: 265934 | F5: 105602 | G5: 77322 | H5: 40911 | I5: =SUM(C5:H5) -> 944739
B6: Cali | C6: 120201 | D6: 168508 | E6: 195620 | F6: 98481 | G6: 62130 | H6: 23429 | I6: =SUM(C6:H6) -> 668369
B7: B/manga | C7: 38127 | D7: 33305 | E7: 45924 | F7: 61562 | G7: 6002 | H7: 10180 | I7: =SUM(C7:H7) -> 195100
B8: C/gena | C8: 117585 | D8: 83838 | E8: 57300 | F8: 20294 | G8: 12086 | H8: 13328 | I8: =SUM(C8:H8) -> 304431
B9: Otras Ciudades | C9: 755665 | D9: 737405 | E9: 504312 | F9: 200497 | G9: 79576 | H9: 45633 | I9: =SUM(C9:H9) -> 2323088
B11: Bogotá | C11: =+C3/$I$3 -> 0.077365468 | D11: =+D3/$I$3 -> 0.34013181 | E11: =+E3/$I$3 -> 0.35571738 | F11: =+F3/$I$3 -> 0.1433005 | G11: =+G3/$I$3 -> 0.046815652 | H11: =+H3/$I$3 -> 0.036669195 | I11: =SUM(C11:H11) -> 1 | K11: Por favor consultar con estadistica Incorporación de ciudades o más regiones fuera de las 6 principales para un aterrizaje más detallado de costos
B12: Barranquilla | C12: =+C4/$I$4 -> 0.34102458 | D12: =+D4/$I$4 -> 0.20458198 | E12: =+E4/$I$4 -> 0.23169199 | F12: =+F4/$I$4 -> 0.13606411 | G12: =+G4/$I$4 -> 0.049282706 | H12: =+H4/$I$4 -> 0.037354642 | I12: =SUM(C12:H12) -> 1
B13: Medellín | C13: =+C5/$I$5 -> 0.14345973 | D13: =+D5/$I$5 -> 0.33812302 | E13: =+E5/$I$5 -> 0.28148938 | F13: =+F5/$I$5 -> 0.11177902 | G13: =+G5/$I$5 -> 0.081844827 | H13: =+H5/$I$5 -> 0.043304024 | I13: =SUM(C13:H13) -> 1
B14: Cali | C14: =+C6/$I$6 -> 0.17984227 | D14: =+D6/$I$6 -> 0.25211822 | E14: =+E6/$I$6 -> 0.29268263 | F14: =+F6/$I$6 -> 0.14734525 | G14: =+G6/$I$6 -> 0.092957633 | H14: =+H6/$I$6 -> 0.03505399 | I14: =SUM(C14:H14) -> 1
B15: B/manga | C15: =+C7/$I$7 -> 0.19542286 | D15: =+D7/$I$7 -> 0.17070733 | E15: =+E7/$I$7 -> 0.23538698 | F15: =+F7/$I$7 -> 0.31554075 | G15: =+G7/$I$7 -> 0.030763711 | H15: =+H7/$I$7 -> 0.05217837 | I15: =SUM(C15:H15) -> 1
B16: C/gena | C16: =+C8/$I$8 -> 0.38624516 | D16: =+D8/$I$8 -> 0.27539245 | E16: =+E8/$I$8 -> 0.18821999 | F16: =+F8/$I$8 -> 0.066662068 | G16: =+G8/$I$8 -> 0.039700293 | H16: =+H8/$I$8 -> 0.043780036 | I16: =SUM(C16:H16) -> 1
B17: Otras Ciudades Principales | C17: =+C9/$I$9 -> 0.32528471 | D17: =+D9/$I$9 -> 0.31742448 | E17: =+E9/$I$9 -> 0.21708691 | F17: =+F9/$I$9 -> 0.086306244 | G17: =+G9/$I$9 -> 0.034254406 | H17: =+H9/$I$9 -> 0.019643251 | I17: =SUM(C17:H17) -> 1
B20: Muestra Técnica de Recolección #1
B21: Ciudades | C21: =COUNTIF(A23:A29,"VERDADERO") -> 0 | D21: =SUM(D23:D29) -> 30.946187 | E21: =SUM(E23:E29) -> 136.05273 | F21: =SUM(F23:F29) -> 142.28695 | G21: =SUM(G23:G29) -> 57.320198 | H21: =SUM(H23:H29) -> 18.726261 | I21: =SUM(I23:I29) -> 14.667678 | J21: Muestra total
B22: Muestra | C22: =SUM(C23:C29) -> 400 | D22: NSE 1 | E22: NSE 2 | F22: NSE 3 | G22: NSE 4 | H22: NSE 5 | I22: NSE 6 | J22: =SUM(J23:J29) -> 400 | K22: Volver al Home
B23: Bogota | C23: =SUM(D23:I23) -> 400 | D23: =+$J$23*C11 -> 30.946187 | E23: =+$J$23*D11 -> 136.05273 | F23: =+$J$23*E11 -> 142.28695 | G23: =+$J$23*F11 -> 57.320198 | H23: =+$J$23*G11 -> 18.726261 | I23: =+$J$23*H11 -> 14.667678 | J23: 400
B24: B/quilla | C24: =SUM(D24:I24) -> 0 | D24: =+$J$24*C12 -> 0 | E24: =+$J$24*D12 -> 0 | F24: =+$J$24*E12 -> 0 | G24: =+$J$24*F12 -> 0 | H24: =+$J$24*G12 -> 0 | I24: =+$J$24*H12 -> 0
B25: M/llin | C25: =SUM(D25:I25) -> 0 | D25: =+$J$25*C13 -> 0 | E25: =+$J$25*D13 -> 0 | F25: =+$J$25*E13 -> 0 | G25: =+$J$25*F13 -> 0 | H25: =+$J$25*G13 -> 0 | I25: =+$J$25*H13 -> 0
B26: Cali | C26: =SUM(D26:I26) -> 0 | D26: =+$J$26*C14 -> 0 | E26: =+$J$26*D14 -> 0 | F26: =+$J$26*E14 -> 0 | G26: =+$J$26*F14 -> 0 | H26: =+$J$26*G14 -> 0 | I26: =+$J$26*H14 -> 0
B27: B/manga | C27: =SUM(D27:I27) -> 0 | D27: =+$J$27*C15 -> 0 | E27: =+$J$27*D15 -> 0 | F27: =+$J$27*E15 -> 0 | G27: =+$J$27*F15 -> 0 | H27: =+$J$27*G15 -> 0 | I27: =+$J$27*H15 -> 0
B28: C/gena | C28: =SUM(D28:I28) -> 0 | D28: =+$J$28*C16 -> 0 | E28: =+$J$28*D16 -> 0 | F28: =+$J$28*E16 -> 0 | G28: =+$J$28*F16 -> 0 | H28: =+$J$28*G16 -> 0 | I28: =+$J$28*H16 -> 0
B29: Otras Ciudades | C29: =SUM(D29:I29) -> 0 | D29: =+$J$29*C17 -> 0 | E29: =+$J$29*D17 -> 0 | F29: =+$J$29*E17 -> 0 | G29: =+$J$29*F17 -> 0 | H29: =+$J$29*G17 -> 0 | I29: =+$J$29*H17 -> 0 | K29: No Ciudades para otras ciudades | L29: 2
K30: No Encuestadores para otras ciudades | L30: 6
B33: Productividad | C33: 4 | F33: 4 | J33: 5 | N33: 5
B34: No Dias | C34: 3 | F34: 3 | J34: 2 | N34: 2
B35: Principal | C35: Muestra | D35: Encuestadores | E35: Costos | F35: Ciudad 1 | G35: Muestra | H35: Encuestadores | I35: Costos | J35: Ciudad 2 | K35: Muestra | L35: Encuestadores | M35: Costos | N35: Ciudad 3 | O35: Muestra | P35: Encuestadores | Q35: Costos
B36: Cúcuta | C36: 100 | D36: 10 | E36: =+((E70*D36)+(F70*D36*C34)) -> 550000 | F36: Valledupar | G36: 50 | H36: 8 | I36: =+((H36*E84)+(F84*H36*F34)) -> 1240000 | J36: Girardot | K36: 150 | O36: Armenia | P36: 50
B37: Cartagena de Indias | C37: 100 | D37: 5 | E37: =+(+E80*D37)+(D37*C34*F80) -> 835000 | F37: Montería | G37: 50 | H37: 6 | I37: =+((H37*F34)*(E71+F71)) -> 1602000 | J37: Neiva | K37: 50 | O37: Pereira | P37: 100
B38: Tunja | C38: 100 | D38: 5 | E38: =+((D38*E81)+(F81*D38*C34)) -> 1510000 | F38: Cajicá | G38: 50 | H38: 3 | I38: =16000*3*H38*2 -> 288000 | J38: Santa Marta | K38: 50 | O38: Ibagué | P38: 100
B39: Manizales | C39: 100 | D39: 8 | E39: =+((D39*E82)+(F82*D39*C34)) -> 1160000 | F39: Chía | G39: 50 | H39: 3 | I39: =28000*3*H39*2 -> 504000 | J39: Villavicencio | K39: 50
B40: Popayán | C40: 50 | D40: 5 | E40: =+((D40*E83)+(F83*D40*C34)) -> 685000 | F40: Mosquera | G40: 50 | I40: =+I38+I39 -> 792000 | J40: Pasto | K40: 50
B41: Total | C41: =SUM(C36:C40) -> 450 | D41: =SUM(D36:D40) -> 33 | E41: =SUM(E36:E40) -> 4740000 | G41: =SUM(G36:G40) -> 250 | H41: =SUM(H36:H40) -> 20 | I41: =SUM(I36:I40) -> 4426000 | K41: =SUM(K36:K40) -> 350 | L41: =SUM(L36:L40) -> 0 | M41: =SUM(M36:M40) -> 0 | O41: =SUM(O36:O40) -> 0 | P41: =SUM(P36:P40) -> 250 | Q41: =SUM(Q36:Q40) -> 0 | R41: =+O41+K41+G41+C41 -> 1050
L42: =+L36*J33*J34 -> 0 | P42: =+P36*N33*N34 -> 500
O43: Total Transp | Q43: =+Q41+M41+I41+E41 -> 9166000
K47: 60800 | L47: 42000
K48: Hotel | L48: Alimentación
K49: =+$K$47*D36*$C$34 -> 1824000 | L49: =+$L$47*$C$34*D36 -> 1260000
...

Sheet MuestraTec2
C2: NSE 1 | D2: NSE 2 | E2: NSE 3 | F2: NSE 4 | G2: NSE 5 | H2: NSE 6 | I2: Total
B3: Bogotá | C3: 175822 | D3: 772989 | E3: 808409 | F3: 325667 | G3: 106394 | H3: 83335 | I3: =SUM(C3:H3) -> 2272616
B4: Barranquilla | C4: 120736 | D4: 72430 | E4: 82028 | F4: 48172 | G4: 17448 | H4: 13225 | I4: =SUM(C4:H4) -> 354039
B5: Medellín | C5: 135532 | D5: 319438 | E5: 265934 | F5: 105602 | G5: 77322 | H5: 40911 | I5: =SUM(C5:H5) -> 944739
B6: Cali | C6: 120201 | D6: 168508 | E6: 195620 | F6: 98481 | G6: 62130 | H6: 23429 | I6: =SUM(C6:H6) -> 668369
B7: B/manga | C7: 38127 | D7: 33305 | E7: 45924 | F7: 61562 | G7: 6002 | H7: 10180 | I7: =SUM(C7:H7) -> 195100
B8: C/gena | C8: 117585 | D8: 83838 | E8: 57300 | F8: 20294 | G8: 12086 | H8: 13328 | I8: =SUM(C8:H8) -> 304431
B9: Otras Ciudades | C9: 755665 | D9: 737405 | E9: 504312 | F9: 200497 | G9: 79576 | H9: 45633 | I9: =SUM(C9:H9) -> 2323088
B11: Bogotá | C11: =+C3/$I$3 -> 0.077365468 | D11: =+D3/$I$3 -> 0.34013181 | E11: =+E3/$I$3 -> 0.35571738 | F11: =+F3/$I$3 -> 0.1433005 | G11: =+G3/$I$3 -> 0.046815652 | H11: =+H3/$I$3 -> 0.036669195 | I11: =SUM(C11:H11) -> 1 | K11: Por favor consultar con estadistica Incorporación de ciudades o más regiones fuera de las 6 principales para un aterrizaje más detallado de costos
B12: Barranquilla | C12: =+C4/$I$4 -> 0.34102458 | D12: =+D4/$I$4 -> 0.20458198 | E12: =+E4/$I$4 -> 0.23169199 | F12: =+F4/$I$4 -> 0.13606411 | G12: =+G4/$I$4 -> 0.049282706 | H12: =+H4/$I$4 -> 0.037354642 | I12: =SUM(C12:H12) -> 1
B13: Medellín | C13: =+C5/$I$5 -> 0.14345973 | D13: =+D5/$I$5 -> 0.33812302 | E13: =+E5/$I$5 -> 0.28148938 | F13: =+F5/$I$5 -> 0.11177902 | G13: =+G5/$I$5 -> 0.081844827 | H13: =+H5/$I$5 -> 0.043304024 | I13: =SUM(C13:H13) -> 1
B14: Cali | C14: =+C6/$I$6 -> 0.17984227 | D14: =+D6/$I$6 -> 0.25211822 | E14: =+E6/$I$6 -> 0.29268263 | F14: =+F6/$I$6 -> 0.14734525 | G14: =+G6/$I$6 -> 0.092957633 | H14: =+H6/$I$6 -> 0.03505399 | I14: =SUM(C14:H14) -> 1
B15: B/manga | C15: =+C7/$I$7 -> 0.19542286 | D15: =+D7/$I$7 -> 0.17070733 | E15: =+E7/$I$7 -> 0.23538698 | F15: =+F7/$I$7 -> 0.31554075 | G15: =+G7/$I$7 -> 0.030763711 | H15: =+H7/$I$7 -> 0.05217837 | I15: =SUM(C15:H15) -> 1
B16: C/gena | C16: =+C8/$I$8 -> 0.38624516 | D16: =+D8/$I$8 -> 0.27539245 | E16: =+E8/$I$8 -> 0.18821999 | F16: =+F8/$I$8 -> 0.066662068 | G16: =+G8/$I$8 -> 0.039700293 | H16: =+H8/$I$8 -> 0.043780036 | I16: =SUM(C16:H16) -> 1
B17: Otras Ciudades Principales | C17: =+C9/$I$9 -> 0.32528471 | D17: =+D9/$I$9 -> 0.31742448 | E17: =+E9/$I$9 -> 0.21708691 | F17: =+F9/$I$9 -> 0.086306244 | G17: =+G9/$I$9 -> 0.034254406 | H17: =+H9/$I$9 -> 0.019643251 | I17: =SUM(C17:H17) -> 1
B20: Muestra Técnica de Recolección #2
B21: Ciudades | C21: =COUNTIF(A23:A29,"VERDADERO") -> 0 | D21: =SUM(D23:D29) -> 0 | E21: =SUM(E23:E29) -> 0 | F21: =SUM(F23:F29) -> 0 | G21: =SUM(G23:G29) -> 0 | H21: =SUM(H23:H29) -> 0 | I21: =SUM(I23:I29) -> 0 | J21: Muestra total
B22: Muestra | C22: =SUM(C23:C29) -> 0 | D22: NSE 1 | E22: NSE 2 | F22: NSE 3 | G22: NSE 4 | H22: NSE 5 | I22: NSE 6 | J22: =SUM(J23:J29) -> 0 | K22: Volver al Home
B23: Bogota | C23: =SUM(D23:I23) -> 0 | D23: =+$J$23*C11 -> 0 | E23: =+$J$23*D11 -> 0 | F23: =+$J$23*E11 -> 0 | G23: =+$J$23*F11 -> 0 | H23: =+$J$23*G11 -> 0 | I23: =+$J$23*H11 -> 0
B24: B/quilla | C24: =SUM(D24:I24) -> 0 | D24: =+$J$24*C12 -> 0 | E24: =+$J$24*D12 -> 0 | F24: =+$J$24*E12 -> 0 | G24: =+$J$24*F12 -> 0 | H24: =+$J$24*G12 -> 0 | I24: =+$J$24*H12 -> 0
B25: M/llin | C25: =SUM(D25:I25) -> 0 | D25: =+$J$25*C13 -> 0 | E25: =+$J$25*D13 -> 0 | F25: =+$J$25*E13 -> 0 | G25: =+$J$25*F13 -> 0 | H25: =+$J$25*G13 -> 0 | I25: =+$J$25*H13 -> 0
B26: Cali | C26: =SUM(D26:I26) -> 0 | D26: =+$J$26*C14 -> 0 | E26: =+$J$26*D14 -> 0 | F26: =+$J$26*E14 -> 0 | G26: =+$J$26*F14 -> 0 | H26: =+$J$26*G14 -> 0 | I26: =+$J$26*H14 -> 0
B27: B/manga | C27: =SUM(D27:I27) -> 0 | D27: =+$J$27*C15 -> 0 | E27: =+$J$27*D15 -> 0 | F27: =+$J$27*E15 -> 0 | G27: =+$J$27*F15 -> 0 | H27: =+$J$27*G15 -> 0 | I27: =+$J$27*H15 -> 0
B28: C/gena | C28: =SUM(D28:I28) -> 0 | D28: =+$J$28*C16 -> 0 | E28: =+$J$28*D16 -> 0 | F28: =+$J$28*E16 -> 0 | G28: =+$J$28*F16 -> 0 | H28: =+$J$28*G16 -> 0 | I28: =+$J$28*H16 -> 0
B29: Otras Ciudades | C29: =SUM(D29:I29) -> 0 | D29: =+$J$29*C17 -> 0 | E29: =+$J$29*D17 -> 0 | F29: =+$J$29*E17 -> 0 | G29: =+$J$29*F17 -> 0 | H29: =+$J$29*G17 -> 0 | I29: =+$J$29*H17 -> 0 | K29: No Ciudades para otras ciudades
K30: No Encuestadores para otras ciudades | L30: =+D41+H41+L41+P41 -> 0
B33: Productividad | C33: 5 | F33: 5 | J33: 5 | N33: 5
B34: No Dias | C34: 4 | F34: 2 | J34: 2 | N34: 2
B35: Principal | C35: Muestra | D35: Encuestadores | E35: Costos | F35: Ciudad 1 | G35: Muestra | H35: Encuestadores | I35: Costos | J35: Ciudad 2 | K35: Muestra | L35: Encuestadores | M35: Costos | N35: Ciudad 3 | O35: Muestra | P35: Encuestadores | Q35: Costos
B41: Total | C41: =SUM(C36:C40) -> 0 | D41: =SUM(D36:D40) -> 0 | E41: =SUM(E36:E40) -> 0 | G41: =SUM(G36:G40) -> 0 | H41: =SUM(H36:H40) -> 0 | I41: =SUM(I36:I40) -> 0 | K41: =SUM(K36:K40) -> 0 | L41: =SUM(L36:L40) -> 0 | M41: =SUM(M36:M40) -> 0 | O41: =SUM(O36:O40) -> 0 | P41: =SUM(P36:P40) -> 0 | Q41: =SUM(Q36:Q40) -> 0 | R41: =+O41+K41+G41+C41 -> 0
D42: =+D36*C33*C34 -> 0 | H42: =+H36*F33*F34 -> 0 | L42: =+L36*J33*J34 -> 0 | P42: =+P36*N33*N34 -> 0
O43: Total Transp | Q43: =+Q41+M41+I41+E41 -> 0
K46: 52000 | L46: 40000
K47: Hotel | L47: Alimentación
J54: Total | K54: =SUM(K48:K53) -> 0 | L54: =SUM(L48:L53) -> 0 | M54: Total Hotel + Alim | N54: =+K54+L54 -> 0
M55: Total Viáticos | N55: =+N54+Q43 -> 0
B58: Ciudad | C58: Pasaje Ida y regreso | D58: Teminales | E58: Total | F58: En ciudad
B59: CARTAGENA | C59: =38000*2 -> 76000 | D59: 26000 | E59: =SUM(C59:D59) -> 102000 | F59: 13000
B60: VALLEDUPAR | C60: =60000*2 -> 120000 | D60: 26000 | E60: =SUM(C60:D60) -> 146000 | F60: 13000
B61: SANTA MARTA | C61: =38000*2 -> 76000 | D61: 26000 | E61: =SUM(C61:D61) -> 102000 | F61: 13000
...

Sheet MYSTERY
A2: =MAX(A3,A4,A5) -> 1 | B2: Tipo de Visita | C2: Complejidad | F2: No. Olas | G2: =+Entradas!D72 -> 1 | H2: No. Olas | I2: =+Entradas!E72 -> 1 | J2: No. Olas | K2: =+Entradas!F72 -> 1 | L2: No. Olas | M2: =+G2+I2+K2 -> 3
A3: =VLOOKUP(C3,Parametros!$B$125:$E$135,4,0) -> 1 | B3: TIPO VISITA 1 | C3: =+Entradas!G16 -> Básica - Video | D3: =+IF(C3="Ninguna",0,1) -> 1
A4: =VLOOKUP(C4,Parametros!$B$125:$E$135,4,0) -> 0 | B4: TIPO VISITA 2 | C4: =+Entradas!J16 -> Ninguna | D4: =+IF(C4="Ninguna",0,1) -> 0
A5: =VLOOKUP(C5,Parametros!$B$125:$E$135,4,0) -> 0 | B5: TIPO VISITA 3 | C5: =+Entradas!M16 -> Ninguna | D5: =+IF(C5="Ninguna",0,1) -> 0 | E5: =+F7+H8+J9 -> 0 | F5: TIPO DE VISITA 1 - SEGMENTO 1 | H5: TIPO DE VISITA 2 - SEGMENTO 2 | J5: TIPO DE VISITA 3 - SEGMENTO 3 | L5: TOTAL ESTUDIO X OLA
A6: Costeo Mystery Shopper | C6: Descripción Costo | D6: Cod. Matrix | E6: Vr. Unitario | F6: CANTIDAD | G6: TOTAL | H6: CANTIDAD | I6: TOTAL | J6: CANTIDAD | K6: TOTAL | L6: CANTIDAD | M6: TOTAL | N6: OBSERVACIONES
A7: Costo Directo | B7: Mystery Shopper | C7: TIPO VISITA 1 | D7: 5418 | E7: =VLOOKUP($C$3,Parametros!$B$109:$D$122,3,0) -> 55000 | F7: =+Entradas!H16 -> 0 | G7: =+F7*$E7*D3 -> 0 | I7: =+H7*$E7 -> 0 | L7: =+F7*$G$2 -> 0 | M7: =+G7*G2 -> 0
A8: Costo Directo | B8: Mystery Shopper | C8: TIPO VISITA 2 | D8: 5418 | E8: =VLOOKUP($C$4,Parametros!$B$109:$D$122,3,0) -> 0 | H8: =+Entradas!K16 -> 0 | I8: =+H8*$E8*D4 -> 0 | L8: =+H8*$I$2 -> 0 | M8: =+I8*I2 -> 0
A9: Costo Directo | B9: Mystery Shopper | C9: TIPO VISITA 3 | D9: 5418 | E9: =VLOOKUP($C$5,Parametros!$B$109:$D$122,3,0) -> 0 | J9: =+Entradas!N16 -> 0 | K9: =+J9*E9*D5 -> 0 | L9: =+J9*$K$2 -> 0 | M9: =+K9*K2 -> 0
A10: Costo Directo | B10: Operación | C10: Coord Campo - Capacitaciones / entrega (PMO) | D10: 5420 | E10: =63211*9.53%+63211 -> 69235.008 | F10: =VLOOKUP($A$3,Parametros!$A$125:$D$135,3,0)*2 -> 4 | G10: =+F10*$E10*D3 -> 276940.03 | H10: =VLOOKUP($A$4,Parametros!$A$125:$D$135,3,0)*2 -> 0 | I10: =+H10*$E10*D4 -> 0 | J10: =VLOOKUP($A$5,Parametros!$A$125:$D$135,3,0)*2 -> 0 | K10: =+J10*$E10*D5 -> 0 | L10: =+(F10*$G$2)+(H10*$I$2)+(J10*$K$2) -> 4 | M10: =+(G10*$G$2)+(I10*$I$2)+(K10*$K$2) -> 276940.03
A11: Costo Directo | B11: Operación | C11: Asist. Campo - capacitaciones / entrega (Coord campo) | D11: 5420 | E11: =63211*9.53%+63211 -> 69235.008 | F11: =+Entradas!D79 -> 4 | G11: =+F11*$E11*D3 -> 276940.03 | H11: =+Entradas!E79 -> 0 | I11: =+H11*$E11*D4 -> 0 | J11: =+Entradas!F79 -> 0 | K11: =+J11*$E11*D5 -> 0 | L11: =+(F11*$G$2)+(H11*$I$2)+(J11*$K$2) -> 4 | M11: =+(G11*$G$2)+(I11*$I$2)+(K11*$K$2) -> 276940.03
A12: Costo Directo | B12: Operación | C12: Coord Campo (PMO) | D12: 5420 | E12: =63211*9.53%+63211 -> 69235.008 | F12: =+Entradas!D80 -> 36 | G12: =+F12*$E12*D3 -> 2492460.3 | H12: =+Entradas!E80 -> 0 | I12: =+H12*$E12*D4 -> 0 | J12: =+Entradas!F80 -> 0 | K12: =+J12*$E12*D5 -> 0 | L12: =+(F12*$G$2)+(H12*$I$2)+(J12*$K$2) -> 36 | M12: =+(G12*$G$2)+(I12*$I$2)+(K12*$K$2) -> 2492460.3
A13: Costo Directo | B13: Operación | C13: Asist. Campo (Coord. Campo) | D13: 5420 | E13: =63211*9.53%+63211 -> 69235.008 | F13: =+Entradas!D81 -> 36 | G13: =+F13*$E13*D3 -> 2492460.3 | H13: =+Entradas!E81 -> 0 | I13: =+H13*$E13*D4 -> 0 | J13: =+Entradas!F81 -> 0 | K13: =+J13*$E13*D5 -> 0 | L13: =+(F13*$G$2)+(H13*$I$2)+(J13*$K$2) -> 36 | M13: =+(G13*$G$2)+(I13*$I$2)+(K13*$K$2) -> 2492460.3
A14: Costo Directo | B14: Operación | C14: Apoyo otra asistencia - Unificación videos | D14: 200 | E14: =63211*9.53%+63211 -> 69235.008 | F14: =VLOOKUP(IF($F$7<=50,50,IF($F$7<=100,100,IF($F$7<=200,200,IF($F$7<=300,300,300)))),Parametros!$H$124:$M$128,2,0) -> 10 | G14: =+F14*$E14*D3 -> 692350.08 | H14: =VLOOKUP(IF($H$8<=50,50,IF($H$8<=100,100,IF($H$8<=200,200,IF($H$8<=300,300,300)))),Parametros!$H$124:$M$128,2,0) -> 10 | I14: =+H14*$E14*D4 -> 0 | J14: =VLOOKUP(IF($J$9<=50,50,IF($J$9<=100,100,IF($J$9<=200,200,IF($J$9<=300,300,300)))),Parametros!$H$124:$M$128,2,0) -> 10 | K14: =+J14*$E14*D5 -> 0 | L14: =+(F14*$G$2)+(H14*$I$2)+(J14*$K$2) -> 30 | M14: =+(G14*$G$2)+(I14*$I$2)+(K14*$K$2) -> 692350.08
A15: Costo Directo | B15: Operación | C15: Apoyo otra asistencia - RMC | D15: 200 | E15: =63211*9.53%+63211 -> 69235.008 | F15: =VLOOKUP(IF($F$7<=50,50,IF($F$7<=100,100,IF($F$7<=200,200,IF($F$7<=300,300,300)))),Parametros!$H$124:$M$128,2,0) -> 10 | G15: =+F15*$E15*D3 -> 692350.08 | H15: =VLOOKUP(IF($H$8<=50,50,IF($H$8<=100,100,IF($H$8<=200,200,IF($H$8<=300,300,300)))),Parametros!$H$124:$M$128,2,0) -> 10 | I15: =+H15*$E15*D4 -> 0 | J15: =VLOOKUP(IF($J$9<=50,50,IF($J$9<=100,100,IF($J$9<=200,200,IF($J$9<=300,300,300)))),Parametros!$H$124:$M$128,2,0) -> 10 | K15: =+J15*$E15*D5 -> 0 | L15: =+(F15*$G$2)+(H15*$I$2)+(J15*$K$2) -> 30 | M15: =+(G15*$G$2)+(I15*$I$2)+(K15*$K$2) -> 692350.08
A16: Costo Directo | C16: Seguimiento Mysterys | F16: =SUM(F7:F9) -> 0 | G16: =SUM(G7:G15) -> 6923500.8 | H16: =SUM(H7:H9) -> 0 | I16: =SUM(I7:I15) -> 0 | J16: =SUM(J7:J9) -> 0 | K16: =SUM(K7:K15) -> 0 | L16: =SUM(L7:L9) -> 0 | M16: =SUM(M7:M15) -> 6923500.8
A17: Costo Directo | B17: CRITICA-Revisión encuestas | C17: TIPO VISITA 1 | D17: 5504 | E17: =102183*9.53%+102183 -> 111921.04 | F17: =(F7/12)*1.1 -> 0 | G17: =+F17*$E17*D3 -> 0 | L17: =+(F17*$G$2)+(H17*$I$2)+(J17*$K$2) -> 0 | M17: =+(G17*$G$2)+(I17*$I$2)+(K17*$K$2) -> 0
A18: Costo Directo | B18: CRITICA-Revisión encuestas | C18: TIPO VISITA 2 | D18: 5504 | E18: =102183*9.53%+102183 -> 111921.04 | H18: =(H8/12)*1.1 -> 0 | I18: =+H18*$E18*D4 -> 0 | L18: =+(F18*$G$2)+(H18*$I$2)+(J18*$K$2) -> 0 | M18: =+(G18*$G$2)+(I18*$I$2)+(K18*$K$2) -> 0
A19: Costo Directo | B19: CRITICA-Revisión encuestas | C19: TIPO VISITA 3 | D19: 5504 | E19: =102183*9.53%+102183 -> 111921.04 | J19: =(J9/12)*1.1 -> 0 | K19: =+J19*$E19*D5 -> 0 | L19: =+(F19*$G$2)+(H19*$I$2)+(J19*$K$2) -> 0 | M19: =+(G19*$G$2)+(I19*$I$2)+(K19*$K$2) -> 0
A20: Costo Directo | B20: CRITICA-Revisión encuestas | C20: Capacitación y entrega | D20: 5504 | E20: =102183*9.53%+102183 -> 111921.04 | F20: =+((2*1)+(4*2))/9 -> 1.1111111 | G20: =+F20*$E20*D3 -> 124356.71 | H20: =+((2*1)+(4*2))/9 -> 1.1111111 | I20: =+H20*$E20*D4 -> 0 | J20: =+((2*1)+(4*2))/9 -> 1.1111111 | K20: =+J20*$E20*D5 -> 0 | L20: =+(F20*$G$2)+(H20*$I$2)+(J20*$K$2) -> 3.3333333 | M20: =+(G20*$G$2)+(I20*$I$2)+(K20*$K$2) -> 124356.71 | N20: El valor para otras olas será del 50% del costo de la ola 1
A21: Costo Directo | B21: CRITICA-Revisión encuestas | C21: Solución a descargos | D21: 5504 | E21: =102183*9.53%+102183 -> 111921.04 | F21: =VLOOKUP(IF($F$7<=50,50,IF($F$7<=100,100,IF($F$7<=200,200,IF($F$7<=300,300,300)))),Parametros!$H$124:$M$128,4,0) -> 1 | G21: =+F21*$E21*D3 -> 111921.04 | H21: =VLOOKUP(IF($H$8<=50,50,IF($H$8<=100,100,IF($H$8<=200,200,IF($H$8<=300,300,300)))),Parametros!$H$124:$M$128,4,0) -> 1 | I21: =+H21*$E21*D4 -> 0 | J21: =VLOOKUP(IF($J$9<=50,50,IF($J$9<=100,100,IF($J$9<=200,200,IF($J$9<=300,300,300)))),Parametros!$H$124:$M$128,4,0) -> 1 | K21: =+J21*$E21*D5 -> 0 | L21: =+(F21*$G$2)+(H21*$I$2)+(J21*$K$2) -> 3 | M21: =+(G21*$G$2)+(I21*$I$2)+(K21*$K$2) -> 111921.04
A22: Costo Directo | C22: Critica | D22: =+D17 -> 5504 | G22: =SUM(G17:G21) -> 236277.75 | I22: =SUM(I17:I21) -> 0 | K22: =SUM(K17:K21) -> 0 | M22: =SUM(M17:M21) -> 236277.75
A23: Costo Directo | B23: Desplazamientos (viaticos) | C23: Desplazamientos (viaticos) | D23: 9997 | E23: 1 | F23: =+Entradas!D73 -> 0 | G23: =+F23*$E23*D3 -> 0 | H23: =+Entradas!E73 -> 0 | I23: =+H23*$E23*D4 -> 0 | J23: =+Entradas!F73 -> 0 | K23: =+J23*$E23*D5 -> 0 | L23: =+(F23*$G$2)+(H23*$I$2)+(J23*$K$2) -> 0 | M23: =+(G23*$G$2)+(I23*$I$2)+(K23*$K$2) -> 0
A24: Costo Directo | B24: Otro tipo de desplazamiento - Tanqueos - consumos | C24: XXXX | D24: 9997 | E24: 1 | F24: =+Entradas!D74 -> 0 | G24: =+F24*$E24*D3 -> 0 | H24: =+Entradas!E74 -> 0 | I24: =+H24*$E24*D4 -> 0 | J24: =+Entradas!F74 -> 0 | K24: =+J24*$E24*D5 -> 0 | L24: =+E24 -> 1 | M24: =+(G24*$G$2)+(I24*$I$2)+(K24*$K$2) -> 0
A25: Costo Directo | C25: Desplazamientos | G25: =SUM(G23:G24) -> 0 | I25: =SUM(I23:I24) -> 0 | K25: =SUM(K23:K24) -> 0 | M25: =SUM(M23:M24) -> 0
