Workbook

Sheet Inicio
S1: Versión 2022-09-22
D7: Formato para carga de muestra a Matrix
D14: Por favor lea atentamente las instrucciones antes de continuar
E19: Este formato ha sido diseñado para facilitar el diligenciamiento de la muestra para los presupuestos en Matrix. Por favor siga las siguientes recomendaciones para garantizar el óptimo funcionamiento
E21: 1. No intente cambiar la estructura del archivo, renombrar hojas, así como tampoco eliminar o insertar filas ya que esto puede generar inconsistencias en la carga de información
E22: 2. La versión del archivo se encuentra en la parte superior derecha en verde, la cual servirá de referencia para cuando nuevas versiones o funcionalidades sean requeridas
E23: 3. Existen tres hojas, las cuales tienen funcionalidades diferentes. Asegúrese de estar usando la correcta para que sus datos sean importados a Matrix correctamente
E24: 4. Dentro de cada hoja están las descripciones de para qué sirve cada una. Su funcionamiento está ligado a la metodología la cual se encuentra restringida según el tipo de hoja a usar
E25: 5. Las hojas en Excel tienen unos espacios en verde claro que indica qué celdas están habilitadas para cargar información. No intente cargar información de otro lugar
E26: 6. Siempre tenga el código DANE de las ciudades que desea ingresar. Esto es fundalmental para incluir la información en Matrix
E27: 7. Si requiere copiar desde un archivo diferente y pegar dentro de alguna de las hojas, procure usar siempre pegar como valores para garantizar la estructura del archivo
E28: 8. Verifique que la información que está agregando es correcta. Incluir un número de propuesta incorrecta puede generar que la información no se suba, o peor aún, dañar un presupuesto que no sea el suyo. Por tanto, siempre haga doble chequeo de la información diligenciada

Sheet Muestra_x_NSE_Poblacional
A1: Subir muestra x NSE usando distribución poblacional
A2: Utlice esta hoja para subir la muestra por municipio utilizando la distribución poblacional. Diligencie toda la información del encabezado y posteriormente agregue todas las filas de muestra escribiendo el código DANE de cada municipio y la muestra total a agregar
A5: =IF(SUM(F8:F257)>0,"Hay uno o más errores. Corríjalos antes de subir el Excel","") -> Hay uno o más errores. Corríjalos antes de subir el Excel
A8: Número Propuesta | E8: =IF(C8="","Debe escribir el número de propuesta","") -> Debe escribir el número de propuesta | F8: =IF(NOT(E8=""),1,0) -> 1 | I8: =IF(ISNUMBER(C8),C8,0) -> 0
A9: Número Alternativa | E9: =IF(C9="","Debe escribir el número de alternativa","") -> Debe escribir el número de alternativa | F9: =IF(NOT(E9=""),1,0) -> 1 | I9: =IF(ISNUMBER(C9),C9,0) -> 0
A10: Metodología | E10: =IF(C10="","Debe seleccionar la metodología","") -> Debe seleccionar la metodología | F10: =IF(NOT(E10=""),1,0) -> 1 | I10: =IF(NOT(ISBLANK(C10)),VLOOKUP(C10,Listados!G2:H8,2,FALSE),"")
A11: Fase | E11: =IF(C11="","Debe seleccionar la fase","") -> Debe seleccionar la fase | F11: =IF(NOT(E11=""),1,0) -> 1 | I11: =IF(NOT(ISBLANK(C11)),VLOOKUP(C11,Listados!G21:H37,2,FALSE),"")
A14: Código DANE | B14: Muestra (cantidad) | C14: Nombre Municipio | D14: Departamento | I14: SENTENCIAS
C15: =IF(NOT(ISBLANK(A15)),VLOOKUP(A15,Listados!$A$3:$D$1252,2,FALSE),"") | D15: =IF(NOT(ISBLANK(A15)),VLOOKUP(A15,Listados!$A$3:$D$1252,4,FALSE),"") | E15: =IF(ISERROR(C15),"El código de ciudad no es válido",IF(AND(NOT(ISNUMBER(B15)),NOT(A15="")),"Escriba la muestra para esta ciudad","")) | F15: =IF(NOT(E15=""),1,0) -> 0 | I15: =IF(AND(NOT(A15=""),ISNUMBER(B15)),"EXEC [dbo].[IQ_DistribuirMuestra_WORK] "&A15&", "&B15&", "&$I$8&", "&$I$11&", "&$I$10&", "&$I$9&";","")
C16: =IF(NOT(ISBLANK(A16)),VLOOKUP(A16,Listados!$A$3:$D$1252,2,FALSE),"") | D16: =IF(NOT(ISBLANK(A16)),VLOOKUP(A16,Listados!$A$3:$D$1252,4,FALSE),"") | E16: =IF(ISERROR(C16),"El código de ciudad no es válido",IF(AND(NOT(ISNUMBER(B16)),NOT(A16="")),"Escriba la muestra para esta ciudad","")) | F16: =IF(NOT(E16=""),1,0) -> 0 | I16: =IF(AND(NOT(A16=""),ISNUMBER(B16)),"EXEC [dbo].[IQ_DistribuirMuestra_WORK] "&A16&", "&B16&", "&$I$8&", "&$I$11&", "&$I$10&", "&$I$9&";","")
C17: =IF(NOT(ISBLANK(A17)),VLOOKUP(A17,Listados!$A$3:$D$1252,2,FALSE),"") | D17: =IF(NOT(ISBLANK(A17)),VLOOKUP(A17,Listados!$A$3:$D$1252,4,FALSE),"") | E17: =IF(ISERROR(C17),"El código de ciudad no es válido",IF(AND(NOT(ISNUMBER(B17)),NOT(A17="")),"Escriba la muestra para esta ciudad","")) | F17: =IF(NOT(E17=""),1,0) -> 0 | I17: =IF(AND(NOT(A17=""),ISNUMBER(B17)),"EXEC [dbo].[IQ_DistribuirMuestra_WORK] "&A17&", "&B17&", "&$I$8&", "&$I$11&", "&$I$10&", "&$I$9&";","")
C18: =IF(NOT(ISBLANK(A18)),VLOOKUP(A18,Listados!$A$3:$D$1252,2,FALSE),"") | D18: =IF(NOT(ISBLANK(A18)),VLOOKUP(A18,Listados!$A$3:$D$1252,4,FALSE),"") | E18: =IF(ISERROR(C18),"El código de ciudad no es válido",IF(AND(NOT(ISNUMBER(B18)),NOT(A18="")),"Escriba la muestra para esta ciudad","")) | F18: =IF(NOT(E18=""),1,0) -> 0 | I18: =IF(AND(NOT(A18=""),ISNUMBER(B18)),"EXEC [dbo].[IQ_DistribuirMuestra_WORK] "&A18&", "&B18&", "&$I$8&", "&$I$11&", "&$I$10&", "&$I$9&";","")
C19: =IF(NOT(ISBLANK(A19)),VLOOKUP(A19,Listados!$A$3:$D$1252,2,FALSE),"") | D19: =IF(NOT(ISBLANK(A19)),VLOOKUP(A19,Listados!$A$3:$D$1252,4,FALSE),"") | E19: =IF(ISERROR(C19),"El código de ciudad no es válido",IF(AND(NOT(ISNUMBER(B19)),NOT(A19="")),"Escriba la muestra para esta ciudad","")) | F19: =IF(NOT(E19=""),1,0) -> 0 | I19: =IF(AND(NOT(A19=""),ISNUMBER(B19)),"EXEC [dbo].[IQ_DistribuirMuestra_WORK] "&A19&", "&B19&", "&$I$8&", "&$I$11&", "&$I$10&", "&$I$9&";","")
C20: =IF(NOT(ISBLANK(A20)),VLOOKUP(A20,Listados!$A$3:$D$1252,2,FALSE),"") | D20: =IF(NOT(ISBLANK(A20)),VLOOKUP(A20,Listados!$A$3:$D$1252,4,FALSE),"") | E20: =IF(ISERROR(C20),"El código de ciudad no es válido",IF(AND(NOT(ISNUMBER(B20)),NOT(A20="")),"Escriba la muestra para esta ciudad","")) | F20: =IF(NOT(E20=""),1,0) -> 0 | I20: =IF(AND(NOT(A20=""),ISNUMBER(B20)),"EXEC [dbo].[IQ_DistribuirMuestra_WORK] "&A20&", "&B20&", "&$I$8&", "&$I$11&", "&$I$10&", "&$I$9&";","")
C21: =IF(NOT(ISBLANK(A21)),VLOOKUP(A21,Listados!$A$3:$D$1252,2,FALSE),"") | D21: =IF(NOT(ISBLANK(A21)),VLOOKUP(A21,Listados!$A$3:$D$1252,4,FALSE),"") | E21: =IF(ISERROR(C21),"El código de ciudad no es válido",IF(AND(NOT(ISNUMBER(B21)),NOT(A21="")),"Escriba la muestra para esta ciudad","")) | F21: =IF(NOT(E21=""),1,0) -> 0 | I21: =IF(AND(NOT(A21=""),ISNUMBER(B21)),"EXEC [dbo].[IQ_DistribuirMuestra_WORK] "&A21&", "&B21&", "&$I$8&", "&$I$11&", "&$I$10&", "&$I$9&";","")
C22: =IF(NOT(ISBLANK(A22)),VLOOKUP(A22,Listados!$A$3:$D$1252,2,FALSE),"") | D22: =IF(NOT(ISBLANK(A22)),VLOOKUP(A22,Listados!$A$3:$D$1252,4,FALSE),"") | E22: =IF(ISERROR(C22),"El código de ciudad no es válido",IF(AND(NOT(ISNUMBER(B22)),NOT(A22="")),"Escriba la muestra para esta ciudad","")) | F22: =IF(NOT(E22=""),1,0) -> 0 | I22: =IF(AND(NOT(A22=""),ISNUMBER(B22)),"EXEC [dbo].[IQ_DistribuirMuestra_WORK] "&A22&", "&B22&", "&$I$8&", "&$I$11&", "&$I$10&", "&$I$9&";","")
C23: =IF(NOT(ISBLANK(A23)),VLOOKUP(A23,Listados!$A$3:$D$1252,2,FALSE),"") | D23: =IF(NOT(ISBLANK(A23)),VLOOKUP(A23,Listados!$A$3:$D$1252,4,FALSE),"") | E23: =IF(ISERROR(C23),"El código de ciudad no es válido",IF(AND(NOT(ISNUMBER(B23)),NOT(A23="")),"Escriba la muestra para esta ciudad","")) | F23: =IF(NOT(E23=""),1,0) -> 0 | I23: =IF(AND(NOT(A23=""),ISNUMBER(B23)),"EXEC [dbo].[IQ_DistribuirMuestra_WORK] "&A23&", "&B23&", "&$I$8&", "&$I$11&", "&$I$10&", "&$I$9&";","")
C24: =IF(NOT(ISBLANK(A24)),VLOOKUP(A24,Listados!$A$3:$D$1252,2,FALSE),"") | D24: =IF(NOT(ISBLANK(A24)),VLOOKUP(A24,Listados!$A$3:$D$1252,4,FALSE),"") | E24: =IF(ISERROR(C24),"El código de ciudad no es válido",IF(AND(NOT(ISNUMBER(B24)),NOT(A24="")),"Escriba la muestra para esta ciudad","")) | F24: =IF(NOT(E24=""),1,0) -> 0 | I24: =IF(AND(NOT(A24=""),ISNUMBER(B24)),"EXEC [dbo].[IQ_DistribuirMuestra_WORK] "&A24&", "&B24&", "&$I$8&", "&$I$11&", "&$I$10&", "&$I$9&";","")
C25: =IF(NOT(ISBLANK(A25)),VLOOKUP(A25,Listados!$A$3:$D$1252,2,FALSE),"") | D25: =IF(NOT(ISBLANK(A25)),VLOOKUP(A25,Listados!$A$3:$D$1252,4,FALSE),"") | E25: =IF(ISERROR(C25),"El código de ciudad no es válido",IF(AND(NOT(ISNUMBER(B25)),NOT(A25="")),"Escriba la muestra para esta ciudad","")) | F25: =IF(NOT(E25=""),1,0) -> 0 | I25: =IF(AND(NOT(A25=""),ISNUMBER(B25)),"EXEC [dbo].[IQ_DistribuirMuestra_WORK] "&A25&", "&B25&", "&$I$8&", "&$I$11&", "&$I$10&", "&$I$9&";","")
C26: =IF(NOT(ISBLANK(A26)),VLOOKUP(A26,Listados!$A$3:$D$1252,2,FALSE),"") | D26: =IF(NOT(ISBLANK(A26)),VLOOKUP(A26,Listados!$A$3:$D$1252,4,FALSE),"") | E26: =IF(ISERROR(C26),"El código de ciudad no es válido",IF(AND(NOT(ISNUMBER(B26)),NOT(A26="")),"Escriba la muestra para esta ciudad","")) | F26: =IF(NOT(E26=""),1,0) -> 0 | I26: =IF(AND(NOT(A26=""),ISNUMBER(B26)),"EXEC [dbo].[IQ_DistribuirMuestra_WORK] "&A26&", "&B26&", "&$I$8&", "&$I$11&", "&$I$10&", "&$I$9&";","")
... C264: =IF(NOT(ISBLANK(A264)),VLOOKUP(A264,Listados!$A$3:$D$1252,2,FALSE),"") | D264: =IF(NOT(ISBLANK(A264)),VLOOKUP(A264,Listados!$A$3:$D$1252,4,FALSE),"") | E264: =IF(ISERROR(C264),"El código de ciudad no es válido",IF(AND(NOT(ISNUMBER(B264)),NOT(A264="")),"Escriba la muestra para esta ciudad","")) | F264: =IF(NOT(E264=""),1,0) -> 0 | I264: =IF(AND(NOT(A264=""),ISNUMBER(B264)),"EXEC [dbo].[IQ_DistribuirMuestra_WORK] "&A264&", "&B264&", "&$I$8&", "&$I$11&", "&$I$10&", "&$I$9&";","")

Sheet Muestra_x_NSE
A1: Subir muestra x NSE
A2: Utlice esta hoja para subir la muestra por municipio escribiendo la muestra para cada nivel socioeconómico. Diligencie toda la información del encabezado y posteriormente agregue todas las filas de muestra escribiendo el código DANE de cada municipio y la muestra a agregar por cada nivel socioeconómico
A5: =IF(SUM(H8:H257)>0,"Hay uno o más errores. Corríjalos antes de subir el Excel","") -> Hay uno o más errores. Corríjalos antes de subir el Excel
A8: Número Propuesta | G8: =IF(C8="","Debe escribir el número de propuesta","") -> Debe escribir el número de propuesta | H8: =IF(NOT(G8=""),1,0) -> 1 | I8: =IF(ISNUMBER(C8),C8,0) -> 0
A9: Número Alternativa | G9: =IF(C9="","Debe escribir el número de alternativa","") -> Debe escribir el número de alternativa | H9: =IF(NOT(G9=""),1,0) -> 1 | I9: =IF(ISNUMBER(C9),C9,0) -> 0
A10: Metodología | G10: =IF(C10="","Debe seleccionar la metodología","") -> Debe seleccionar la metodología | H10: =IF(NOT(G10=""),1,0) -> 1 | I10: =IF(NOT(ISBLANK(C10)),VLOOKUP(C10,Listados!G2:H8,2,FALSE),"")
A11: Fase | G11: =IF(C11="","Debe seleccionar la fase","") -> Debe seleccionar la fase | H11: =IF(NOT(G11=""),1,0) -> 1 | I11: =IF(NOT(ISBLANK(C11)),VLOOKUP(C11,Listados!G21:H37,2,FALSE),"")
A14: Código DANE | B14: NSE 1,2,3 | C14: NSE 4 | D14: NSE 5 | E14: Nombre Municipio | F14: Departamento | I14: SENTENCIAS
E15: =IF(NOT(ISBLANK(A15)),VLOOKUP(A15,Listados!$A$3:$D$1252,2,FALSE),"") | F15: =IF(NOT(ISBLANK(A15)),VLOOKUP(A15,Listados!$A$3:$D$1252,4,FALSE),"") | G15: =IF(ISERROR(E15),"El código de ciudad no es válido",IF(AND(NOT(SUM(B15:D15)>0),NOT(A15="")),"Escriba la muestra para esta ciudad","")) | H15: =IF(NOT(G15=""),1,0) -> 0 | I15: =_xlfn.CONCAT(IF(AND(NOT(A15=""),ISNUMBER(B15)),"EXEC [dbo].[IQ_InsertarMuestra_WORK] "&A15&", "&B15&", 30, "&$I$8&", "&$I$11&", "&$I$10&", "&$I$9&";",""),IF(AND(NOT(A15=""),ISNUMBER(C15)),"EXEC [dbo].[IQ_InsertarMuestra_WORK] "&A15&", "&C15&", 20, "&$I$8&", "&$I$11&", "&$I$10&", "&$I$9&";",""),IF(AND(NOT(A15=""),ISNUMBER(D15)),"EXEC [dbo].[IQ_InsertarMuestra_WORK] "&A15&", "&D15&", 10, "&$I$8&", "&$I$11&", "&$I$10&", "&$I$9&";",""))
E16: =IF(NOT(ISBLANK(A16)),VLOOKUP(A16,Listados!$A$3:$D$1252,2,FALSE),"") | F16: =IF(NOT(ISBLANK(A16)),VLOOKUP(A16,Listados!$A$3:$D$1252,4,FALSE),"") | G16: =IF(ISERROR(E16),"El código de ciudad no es válido",IF(AND(NOT(ISNUMBER(SUM(B16:D16))),NOT(A16="")),"Escriba la muestra para esta ciudad","")) | H16: =IF(NOT(G16=""),1,0) -> 0 | I16: =_xlfn.CONCAT(IF(AND(NOT(A16=""),ISNUMBER(B16)),"EXEC [dbo].[IQ_InsertarMuestra_WORK] "&A16&", "&B16&", 30, "&$I$8&", "&$I$11&", "&$I$10&", "&$I$9&";",""),IF(AND(NOT(A16=""),ISNUMBER(C16)),"EXEC [dbo].[IQ_InsertarMuestra_WORK] "&A16&", "&C16&", 20, "&$I$8&", "&$I$11&", "&$I$10&", "&$I$9&";",""),IF(AND(NOT(A16=""),ISNUMBER(D16)),"EXEC [dbo].[IQ_InsertarMuestra_WORK] "&A16&", "&D16&", 10, "&$I$8&", "&$I$11&", "&$I$10&", "&$I$9&";",""))
E17: =IF(NOT(ISBLANK(A17)),VLOOKUP(A17,Listados!$A$3:$D$1252,2,FALSE),"") | F17: =IF(NOT(ISBLANK(A17)),VLOOKUP(A17,Listados!$A$3:$D$1252,4,FALSE),"") | G17: =IF(ISERROR(E17),"El código de ciudad no es válido",IF(AND(NOT(ISNUMBER(SUM(B17:D17))),NOT(A17="")),"Escriba la muestra para esta ciudad","")) | H17: =IF(NOT(G17=""),1,0) -> 0 | I17: =_xlfn.CONCAT(IF(AND(NOT(A17=""),ISNUMBER(B17)),"EXEC [dbo].[IQ_InsertarMuestra_WORK] "&A17&", "&B17&", 30, "&$I$8&", "&$I$11&", "&$I$10&", "&$I$9&";",""),IF(AND(NOT(A17=""),ISNUMBER(C17)),"EXEC [dbo].[IQ_InsertarMuestra_WORK] "&A17&", "&C17&", 20, "&$I$8&", "&$I$11&", "&$I$10&", "&$I$9&";",""),IF(AND(NOT(A17=""),ISNUMBER(D17)),"EXEC [dbo].[IQ_InsertarMuestra_WORK] "&A17&", "&D17&", 10, "&$I$8&", "&$I$11&", "&$I$10&", "&$I$9&";",""))
E18: =IF(NOT(ISBLANK(A18)),VLOOKUP(A18,Listados!$A$3:$D$1252,2,FALSE),"") | F18: =IF(NOT(ISBLANK(A18)),VLOOKUP(A18,Listados!$A$3:$D$1252,4,FALSE),"") | G18: =IF(ISERROR(E18),"El código de ciudad no es válido",IF(AND(NOT(ISNUMBER(SUM(B18:D18))),NOT(A18="")),"Escriba la muestra para esta ciudad","")) | H18: =IF(NOT(G18=""),1,0) -> 0 | I18: =_xlfn.CONCAT(IF(AND(NOT(A18=""),ISNUMBER(B18)),"EXEC [dbo].[IQ_InsertarMuestra_WORK] "&A18&", "&B18&", 30, "&$I$8&", "&$I$11&", "&$I$10&", "&$I$9&";",""),IF(AND(NOT(A18=""),ISNUMBER(C18)),"EXEC [dbo].[IQ_InsertarMuestra_WORK] "&A18&", "&C18&", 20, "&$I$8&", "&$I$11&", "&$I$10&", "&$I$9&";",""),IF(AND(NOT(A18=""),ISNUMBER(D18)),"EXEC [dbo].[IQ_InsertarMuestra_WORK] "&A18&", "&D18&", 10, "&$I$8&", "&$I$11&", "&$I$10&", "&$I$9&";",""))
E19: =IF(NOT(ISBLANK(A19)),VLOOKUP(A19,Listados!$A$3:$D$1252,2,FALSE),"") | F19: =IF(NOT(ISBLANK(A19)),VLOOKUP(A19,Listados!$A$3:$D$1252,4,FALSE),"") | G19: =IF(ISERROR(E19),"El código de ciudad no es válido",IF(AND(NOT(ISNUMBER(SUM(B19:D19))),NOT(A19="")),"Escriba la muestra para esta ciudad","")) | H19: =IF(NOT(G19=""),1,0) -> 0 | I19: =_xlfn.CONCAT(IF(AND(NOT(A19=""),ISNUMBER(B19)),"EXEC [dbo].[IQ_InsertarMuestra_WORK] "&A19&", "&B19&", 30, "&$I$8&", "&$I$11&", "&$I$10&", "&$I$9&";",""),IF(AND(NOT(A19=""),ISNUMBER(C19)),"EXEC [dbo].[IQ_InsertarMuestra_WORK] "&A19&", "&C19&", 20, "&$I$8&", "&$I$11&", "&$I$10&", "&$I$9&";",""),IF(AND(NOT(A19=""),ISNUMBER(D19)),"EXEC [dbo].[IQ_InsertarMuestra_WORK] "&A19&", "&D19&", 10, "&$I$8&", "&$I$11&", "&$I$10&", "&$I$9&";",""))
E20: =IF(NOT(ISBLANK(A20)),VLOOKUP(A20,Listados!$A$3:$D$1252,2,FALSE),"") | F20: =IF(NOT(ISBLANK(A20)),VLOOKUP(A20,Listados!$A$3:$D$1252,4,FALSE),"") | G20: =IF(ISERROR(E20),"El código de ciudad no es válido",IF(AND(NOT(ISNUMBER(SUM(B20:D20))),NOT(A20="")),"Escriba la muestra para esta ciudad","")) | H20: =IF(NOT(G20=""),1,0) -> 0 | I20: =_xlfn.CONCAT(IF(AND(NOT(A20=""),ISNUMBER(B20)),"EXEC [dbo].[IQ_InsertarMuestra_WORK] "&A20&", "&B20&", 30, "&$I$8&", "&$I$11&", "&$I$10&", "&$I$9&";",""),IF(AND(NOT(A20=""),ISNUMBER(C20)),"EXEC [dbo].[IQ_InsertarMuestra_WORK] "&A20&", "&C20&", 20, "&$I$8&", "&$I$11&", "&$I$10&", "&$I$9&";",""),IF(AND(NOT(A20=""),ISNUMBER(D20)),"EXEC [dbo].[IQ_InsertarMuestra_WORK] "&A20&", "&D20&", 10, "&$I$8&", "&$I$11&", "&$I$10&", "&$I$9&";",""))
E21: =IF(NOT(ISBLANK(A21)),VLOOKUP(A21,Listados!$A$3:$D$1252,2,FALSE),"") | F21: =IF(NOT(ISBLANK(A21)),VLOOKUP(A21,Listados!$A$3:$D$1252,4,FALSE),"") | G21: =IF(ISERROR(E21),"El código de ciudad no es válido",IF(AND(NOT(ISNUMBER(SUM(B21:D21))),NOT(A21="")),"Escriba la muestra para esta ciudad","")) | H21: =IF(NOT(G21=""),1,0) -> 0 | I21: =_xlfn.CONCAT(IF(AND(NOT(A21=""),ISNUMBER(B21)),"EXEC [dbo].[IQ_InsertarMuestra_WORK] "&A21&", "&B21&", 30, "&$I$8&", "&$I$11&", "&$I$10&", "&$I$9&";",""),IF(AND(NOT(A21=""),ISNUMBER(C21)),"EXEC [dbo].[IQ_InsertarMuestra_WORK] "&A21&", "&C21&", 20, "&$I$8&", "&$I$11&", "&$I$10&", "&$I$9&";",""),IF(AND(NOT(A21=""),ISNUMBER(D21)),"EXEC [dbo].[IQ_InsertarMuestra_WORK] "&A21&", "&D21&", 10, "&$I$8&", "&$I$11&", "&$I$10&", "&$I$9&";",""))
E22: =IF(NOT(ISBLANK(A22)),VLOOKUP(A22,Listados!$A$3:$D$1252,2,FALSE),"") | F22: =IF(NOT(ISBLANK(A22)),VLOOKUP(A22,Listados!$A$3:$D$1252,4,FALSE),"") | G22: =IF(ISERROR(E22),"El código de ciudad no es válido",IF(AND(NOT(ISNUMBER(SUM(B22:D22))),NOT(A22="")),"Escriba la muestra para esta ciudad","")) | H22: =IF(NOT(G22=""),1,0) -> 0 | I22: =_xlfn.CONCAT(IF(AND(NOT(A22=""),ISNUMBER(B22)),"EXEC [dbo].[IQ_InsertarMuestra_WORK] "&A22&", "&B22&", 30, "&$I$8&", "&$I$11&", "&$I$10&", "&$I$9&";",""),IF(AND(NOT(A22=""),ISNUMBER(C22)),"EXEC [dbo].[IQ_InsertarMuestra_WORK] "&A22&", "&C22&", 20, "&$I$8&", "&$I$11&", "&$I$10&", "&$I$9&";",""),IF(AND(NOT(A22=""),ISNUMBER(D22)),"EXEC [dbo].[IQ_InsertarMuestra_WORK] "&A22&", "&D22&", 10, "&$I$8&", "&$I$11&", "&$I$10&", "&$I$9&";",""))
E23: =IF(NOT(ISBLANK(A23)),VLOOKUP(A23,Listados!$A$3:$D$1252,2,FALSE),"") | F23: =IF(NOT(ISBLANK(A23)),VLOOKUP(A23,Listados!$A$3:$D$1252,4,FALSE),"") | G23: =IF(ISERROR(E23),"El código de ciudad no es válido",IF(AND(NOT(ISNUMBER(SUM(B23:D23))),NOT(A23="")),"Escriba la muestra para esta ciudad","")) | H23: =IF(NOT(G23=""),1,0) -> 0 | I23: =_xlfn.CONCAT(IF(AND(NOT(A23=""),ISNUMBER(B23)),"EXEC [dbo].[IQ_InsertarMuestra_WORK] "&A23&", "&B23&", 30, "&$I$8&", "&$I$11&", "&$I$10&", "&$I$9&";",""),IF(AND(NOT(A23=""),ISNUMBER(C23)),"EXEC [dbo].[IQ_InsertarMuestra_WORK] "&A23&", "&C23&", 20, "&$I$8&", "&$I$11&", "&$I$10&", "&$I$9&";",""),IF(AND(NOT(A23=""),ISNUMBER(D23)),"EXEC [dbo].[IQ_InsertarMuestra_WORK] "&A23&", "&D23&", 10, "&$I$8&", "&$I$11&", "&$I$10&", "&$I$9&";",""))
E24: =IF(NOT(ISBLANK(A24)),VLOOKUP(A24,Listados!$A$3:$D$1252,2,FALSE),"") | F24: =IF(NOT(ISBLANK(A24)),VLOOKUP(A24,Listados!$A$3:$D$1252,4,FALSE),"") | G24: =IF(ISERROR(E24),"El código de ciudad no es válido",IF(AND(NOT(ISNUMBER(SUM(B24:D24))),NOT(A24="")),"Escriba la muestra para esta ciudad","")) | H24: =IF(NOT(G24=""),1,0) -> 0 | I24: =_xlfn.CONCAT(IF(AND(NOT(A24=""),ISNUMBER(B24)),"EXEC [dbo].[IQ_InsertarMuestra_WORK] "&A24&", "&B24&", 30, "&$I$8&", "&$I$11&", "&$I$10&", "&$I$9&";",""),IF(AND(NOT(A24=""),ISNUMBER(C24)),"EXEC [dbo].[IQ_InsertarMuestra_WORK] "&A24&", "&C24&", 20, "&$I$8&", "&$I$11&", "&$I$10&", "&$I$9&";",""),IF(AND(NOT(A24=""),ISNUMBER(D24)),"EXEC [dbo].[IQ_InsertarMuestra_WORK] "&A24&", "&D24&", 10, "&$I$8&", "&$I$11&", "&$I$10&", "&$I$9&";",""))
E25: =IF(NOT(ISBLANK(A25)),VLOOKUP(A25,Listados!$A$3:$D$1252,2,FALSE),"") | F25: =IF(NOT(ISBLANK(A25)),VLOOKUP(A25,Listados!$A$3:$D$1252,4,FALSE),"") | G25: =IF(ISERROR(E25),"El código de ciudad no es válido",IF(AND(NOT(ISNUMBER(SUM(B25:D25))),NOT(A25="")),"Escriba la muestra para esta ciudad","")) | H25: =IF(NOT(G25=""),1,0) -> 0 | I25: =_xlfn.CONCAT(IF(AND(NOT(A25=""),ISNUMBER(B25)),"EXEC [dbo].[IQ_InsertarMuestra_WORK] "&A25&", "&B25&", 30, "&$I$8&", "&$I$11&", "&$I$10&", "&$I$9&";",""),IF(AND(NOT(A25=""),ISNUMBER(C25)),"EXEC [dbo].[IQ_InsertarMuestra_WORK] "&A25&", "&C25&", 20, "&$I$8&", "&$I$11&", "&$I$10&", "&$I$9&";",""),IF(AND(NOT(A25=""),ISNUMBER(D25)),"EXEC [dbo].[IQ_InsertarMuestra_WORK] "&A25&", "&D25&", 10, "&$I$8&", "&$I$11&", "&$I$10&", "&$I$9&";",""))
E26: =IF(NOT(ISBLANK(A26)),VLOOKUP(A26,Listados!$A$3:$D$1252,2,FALSE),"") | F26: =IF(NOT(ISBLANK(A26)),VLOOKUP(A26,Listados!$A$3:$D$1252,4,FALSE),"") | G26: =IF(ISERROR(E26),"El código de ciudad no es válido",IF(AND(NOT(ISNUMBER(SUM(B26:D26))),NOT(A26="")),"Escriba la muestra para esta ciudad","")) | H26: =IF(NOT(G26=""),1,0) -> 0 | I26: =_xlfn.CONCAT(IF(AND(NOT(A26=""),ISNUMBER(B26)),"EXEC [dbo].[IQ_InsertarMuestra_WORK] "&A26&", "&B26&", 30, "&$I$8&", "&$I$11&", "&$I$10&", "&$I$9&";",""),IF(AND(NOT(A26=""),ISNUMBER(C26)),"EXEC [dbo].[IQ_InsertarMuestra_WORK] "&A26&", "&C26&", 20, "&$I$8&", "&$I$11&", "&$I$10&", "&$I$9&";",""),IF(AND(NOT(A26=""),ISNUMBER(D26)),"EXEC [dbo].[IQ_InsertarMuestra_WORK] "&A26&", "&D26&", 10, "&$I$8&", "&$I$11&", "&$I$10&", "&$I$9&";",""))
E27: =IF(NOT(ISBLANK(A27)),VLOOKUP(A27,Listados!$A$3:$D$1252,2,FALSE),"") | F27: =IF(NOT(ISBLANK(A27)),VLOOKUP(A27,Listados!$A$3:$D$1252,4,FALSE),"") | G27: =IF(ISERROR(E27),"El código de ciudad no es válido",IF(AND(NOT(ISNUMBER(SUM(B27:D27))),NOT(A27="")),"Escriba la muestra para esta ciudad","")) | H27: =IF(NOT(G27=""),1,0) -> 0 | I27: =_xlfn.CONCAT(IF(AND(NOT(A27=""),ISNUMBER(B27)),"EXEC [dbo].[IQ_InsertarMuestra_WORK] "&A27&", "&B27&", 30, "&$I$8&", "&$I$11&", "&$I$10&", "&$I$9&";",""),IF(AND(NOT(A27=""),ISNUMBER(C27)),"EXEC [dbo].[IQ_InsertarMuestra_WORK] "&A27&", "&C27&", 20, "&$I$8&", "&$I$11&", "&$I$10&", "&$I$9&";",""),IF(AND(NOT(A27=""),ISNUMBER(D27)),"EXEC [dbo].[IQ_InsertarMuestra_WORK] "&A27&", "&D27&", 10, "&$I$8&", "&$I$11&", "&$I$10&", "&$I$9&";",""))
... E264: =IF(NOT(ISBLANK(A264)),VLOOKUP(A264,Listados!$A$3:$D$1252,2,FALSE),"") | F264: =IF(NOT(ISBLANK(A264)),VLOOKUP(A264,Listados!$A$3:$D$1252,4,FALSE),"") | G264: =IF(ISERROR(E264),"El código de ciudad no es válido",IF(AND(NOT(ISNUMBER(SUM(B264:D264))),NOT(A264="")),"Escriba la muestra para esta ciudad","")) | H264: =IF(NOT(G264=""),1,0) -> 0 | I264: =_xlfn.CONCAT(IF(AND(NOT(A264=""),ISNUMBER(B264)),"EXEC [dbo].[IQ_InsertarMuestra_WORK] "&A264&", "&B264&", 30, "&$I$8&", "&$I$11&", "&$I$10&", "&$I$9&";",""),IF(AND(NOT(A264=""),ISNUMBER(C264)),"EXEC [dbo].[IQ_InsertarMuestra_WORK] "&A264&", "&C264&", 20, "&$I$8&", "&$I$11&", "&$I$10&", "&$I$9&";",""),IF(AND(NOT(A264=""),ISNUMBER(D264)),"EXEC [dbo].[IQ_InsertarMuestra_WORK] "&A264&", "&D264&", 10, "&$I$8&", "&$I$11&", "&$I$10&", "&$I$9&";",""))

Sheet Muestra_x_Dificultad
A1: Subir muestra x Dificultad
A2: Utlice esta hoja para subir la muestra por municipio escribiendo la muestra por dificultad. Diligencie toda la información del encabezado y posteriormente agregue todas las filas de muestra escribiendo el código DANE de cada municipio y la muestra por dificultad
A5: =IF(SUM(G8:G257)>0,"Hay uno o más errores. Corríjalos antes de subir el Excel","") -> Hay uno o más errores. Corríjalos antes de subir el Excel
A8: Número Propuesta | F8: =IF(C8="","Debe escribir el número de propuesta","") -> Debe escribir el número de propuesta | G8: =IF(NOT(F8=""),1,0) -> 1 | I8: =IF(ISNUMBER(C8),C8,0) -> 0
A9: Número Alternativa | F9: =IF(C9="","Debe escribir el número de alternativa","") -> Debe escribir el número de alternativa | G9: =IF(NOT(F9=""),1,0) -> 1 | I9: =IF(ISNUMBER(C9),C9,0) -> 0
A10: Metodología | F10: =IF(C10="","Debe seleccionar la metodología","") -> Debe seleccionar la metodología | G10: =IF(NOT(F10=""),1,0) -> 1 | I10: =IF(NOT(ISBLANK(C10)),VLOOKUP(C10,Listados!G12:H17,2,FALSE),"")
A11: Fase | F11: =IF(C11="","Debe seleccionar la fase","") -> Debe seleccionar la fase | G11: =IF(NOT(F11=""),1,0) -> 1 | I11: =IF(NOT(ISBLANK(C11)),VLOOKUP(C11,Listados!G21:H37,2,FALSE),"")
A14: Código DANE | B14: ALTA DIFICULTAD | C14: BAJA DIFICULTAD | D14: Nombre Municipio | E14: Departamento | I14: SENTENCIAS
D15: =IF(NOT(ISBLANK(A15)),VLOOKUP(A15,Listados!$A$3:$D$1252,2,FALSE),"") | E15: =IF(NOT(ISBLANK(A15)),VLOOKUP(A15,Listados!$A$3:$D$1252,4,FALSE),"") | F15: =IF(ISERROR(D15),"El código de ciudad no es válido",IF(AND(NOT(SUM(B15:C15)>0),NOT(A15="")),"Escriba la muestra para esta ciudad","")) | G15: =IF(NOT(F15=""),1,0) -> 0 | I15: =_xlfn.CONCAT(IF(AND(NOT(A15=""),ISNUMBER(B15)),"EXEC [dbo].[IQ_InsertarMuestra_WORK] "&A15&", "&B15&", 40, "&$I$8&", "&$I$11&", "&$I$10&", "&$I$9&";",""),IF(AND(NOT(A15=""),ISNUMBER(C15)),"EXEC [dbo].[IQ_InsertarMuestra_WORK] "&A15&", "&C15&", 50, "&$I$8&", "&$I$11&", "&$I$10&", "&$I$9&";",""))
D16: =IF(NOT(ISBLANK(A16)),VLOOKUP(A16,Listados!$A$3:$D$1252,2,FALSE),"") | E16: =IF(NOT(ISBLANK(A16)),VLOOKUP(A16,Listados!$A$3:$D$1252,4,FALSE),"") | F16: =IF(ISERROR(D16),"El código de ciudad no es válido",IF(AND(NOT(ISNUMBER(SUM(B16:C16))),NOT(A16="")),"Escriba la muestra para esta ciudad","")) | G16: =IF(NOT(F16=""),1,0) -> 0 | I16: =_xlfn.CONCAT(IF(AND(NOT(A16=""),ISNUMBER(B16)),"EXEC [dbo].[IQ_InsertarMuestra_WORK] "&A16&", "&B16&", 40, "&$I$8&", "&$I$11&", "&$I$10&", "&$I$9&";",""),IF(AND(NOT(A16=""),ISNUMBER(C16)),"EXEC [dbo].[IQ_InsertarMuestra_WORK] "&A16&", "&C16&", 50, "&$I$8&", "&$I$11&", "&$I$10&", "&$I$9&";",""))
D17: =IF(NOT(ISBLANK(A17)),VLOOKUP(A17,Listados!$A$3:$D$1252,2,FALSE),"") | E17: =IF(NOT(ISBLANK(A17)),VLOOKUP(A17,Listados!$A$3:$D$1252,4,FALSE),"") | F17: =IF(ISERROR(D17),"El código de ciudad no es válido",IF(AND(NOT(ISNUMBER(SUM(B17:C17))),NOT(A17="")),"Escriba la muestra para esta ciudad","")) | G17: =IF(NOT(F17=""),1,0) -> 0 | I17: =_xlfn.CONCAT(IF(AND(NOT(A17=""),ISNUMBER(B17)),"EXEC [dbo].[IQ_InsertarMuestra_WORK] "&A17&", "&B17&", 40, "&$I$8&", "&$I$11&", "&$I$10&", "&$I$9&";",""),IF(AND(NOT(A17=""),ISNUMBER(C17)),"EXEC [dbo].[IQ_InsertarMuestra_WORK] "&A17&", "&C17&", 50, "&$I$8&", "&$I$11&", "&$I$10&", "&$I$9&";",""))
D18: =IF(NOT(ISBLANK(A18)),VLOOKUP(A18,Listados!$A$3:$D$1252,2,FALSE),"") | E18: =IF(NOT(ISBLANK(A18)),VLOOKUP(A18,Listados!$A$3:$D$1252,4,FALSE),"") | F18: =IF(ISERROR(D18),"El código de ciudad no es válido",IF(AND(NOT(ISNUMBER(SUM(B18:C18))),NOT(A18="")),"Escriba la muestra para esta ciudad","")) | G18: =IF(NOT(F18=""),1,0) -> 0 | I18: =_xlfn.CONCAT(IF(AND(NOT(A18=""),ISNUMBER(B18)),"EXEC [dbo].[IQ_InsertarMuestra_WORK] "&A18&", "&B18&", 40, "&$I$8&", "&$I$11&", "&$I$10&", "&$I$9&";",""),IF(AND(NOT(A18=""),ISNUMBER(C18)),"EXEC [dbo].[IQ_InsertarMuestra_WORK] "&A18&", "&C18&", 50, "&$I$8&", "&$I$11&", "&$I$10&", "&$I$9&";",""))
D19: =IF(NOT(ISBLANK(A19)),VLOOKUP(A19,Listados!$A$3:$D$1252,2,FALSE),"") | E19: =IF(NOT(ISBLANK(A19)),VLOOKUP(A19,Listados!$A$3:$D$1252,4,FALSE),"") | F19: =IF(ISERROR(D19),"El código de ciudad no es válido",IF(AND(NOT(ISNUMBER(SUM(B19:C19))),NOT(A19="")),"Escriba la muestra para esta ciudad","")) | G19: =IF(NOT(F19=""),1,0) -> 0 | I19: =_xlfn.CONCAT(IF(AND(NOT(A19=""),ISNUMBER(B19)),"EXEC [dbo].[IQ_InsertarMuestra_WORK] "&A19&", "&B19&", 40, "&$I$8&", "&$I$11&", "&$I$10&", "&$I$9&";",""),IF(AND(NOT(A19=""),ISNUMBER(C19)),"EXEC [dbo].[IQ_InsertarMuestra_WORK] "&A19&", "&C19&", 50, "&$I$8&", "&$I$11&", "&$I$10&", "&$I$9&";",""))
D20: =IF(NOT(ISBLANK(A20)),VLOOKUP(A20,Listados!$A$3:$D$1252,2,FALSE),"") | E20: =IF(NOT(ISBLANK(A20)),VLOOKUP(A20,Listados!$A$3:$D$1252,4,FALSE),"") | F20: =IF(ISERROR(D20),"El código de ciudad no es válido",IF(AND(NOT(ISNUMBER(SUM(B20:C20))),NOT(A20="")),"Escriba la muestra para esta ciudad","")) | G20: =IF(NOT(F20=""),1,0) -> 0 | I20: =_xlfn.CONCAT(IF(AND(NOT(A20=""),ISNUMBER(B20)),"EXEC [dbo].[IQ_InsertarMuestra_WORK] "&A20&", "&B20&", 40, "&$I$8&", "&$I$11&", "&$I$10&", "&$I$9&";",""),IF(AND(NOT(A20=""),ISNUMBER(C20)),"EXEC [dbo].[IQ_InsertarMuestra_WORK] "&A20&", "&C20&", 50, "&$I$8&", "&$I$11&", "&$I$10&", "&$I$9&";",""))
D21: =IF(NOT(ISBLANK(A21)),VLOOKUP(A21,Listados!$A$3:$D$1252,2,FALSE),"") | E21: =IF(NOT(ISBLANK(A21)),VLOOKUP(A21,Listados!$A$3:$D$1252,4,FALSE),"") | F21: =IF(ISERROR(D21),"El código de ciudad no es válido",IF(AND(NOT(ISNUMBER(SUM(B21:C21))),NOT(A21="")),"Escriba la muestra para esta ciudad","")) | G21: =IF(NOT(F21=""),1,0) -> 0 | I21: =_xlfn.CONCAT(IF(AND(NOT(A21=""),ISNUMBER(B21)),"EXEC [dbo].[IQ_InsertarMuestra_WORK] "&A21&", "&B21&", 40, "&$I$8&", "&$I$11&", "&$I$10&", "&$I$9&";",""),IF(AND(NOT(A21=""),ISNUMBER(C21)),"EXEC [dbo].[IQ_InsertarMuestra_WORK] "&A21&", "&C21&", 50, "&$I$8&", "&$I$11&", "&$I$10&", "&$I$9&";",""))
D22: =IF(NOT(ISBLANK(A22)),VLOOKUP(A22,Listados!$A$3:$D$1252,2,FALSE),"") | E22: =IF(NOT(ISBLANK(A22)),VLOOKUP(A22,Listados!$A$3:$D$1252,4,FALSE),"") | F22: =IF(ISERROR(D22),"El código de ciudad no es válido",IF(AND(NOT(ISNUMBER(SUM(B22:C22))),NOT(A22="")),"Escriba la muestra para esta ciudad","")) | G22: =IF(NOT(F22=""),1,0) -> 0 | I22: =_xlfn.CONCAT(IF(AND(NOT(A22=""),ISNUMBER(B22)),"EXEC [dbo].[IQ_InsertarMuestra_WORK] "&A22&", "&B22&", 40, "&$I$8&", "&$I$11&", "&$I$10&", "&$I$9&";",""),IF(AND(NOT(A22=""),ISNUMBER(C22)),"EXEC [dbo].[IQ_InsertarMuestra_WORK] "&A22&", "&C22&", 50, "&$I$8&", "&$I$11&", "&$I$10&", "&$I$9&";",""))
D23: =IF(NOT(ISBLANK(A23)),VLOOKUP(A23,Listados!$A$3:$D$1252,2,FALSE),"") | E23: =IF(NOT(ISBLANK(A23)),VLOOKUP(A23,Listados!$A$3:$D$1252,4,FALSE),"") | F23: =IF(ISERROR(D23),"El código de ciudad no es válido",IF(AND(NOT(ISNUMBER(SUM(B23:C23))),NOT(A23="")),"Escriba la muestra para esta ciudad","")) | G23: =IF(NOT(F23=""),1,0) -> 0 | I23: =_xlfn.CONCAT(IF(AND(NOT(A23=""),ISNUMBER(B23)),"EXEC [dbo].[IQ_InsertarMuestra_WORK] "&A23&", "&B23&", 40, "&$I$8&", "&$I$11&", "&$I$10&", "&$I$9&";",""),IF(AND(NOT(A23=""),ISNUMBER(C23)),"EXEC [dbo].[IQ_InsertarMuestra_WORK] "&A23&", "&C23&", 50, "&$I$8&", "&$I$11&", "&$I$10&", "&$I$9&";",""))
D24: =IF(NOT(ISBLANK(A24)),VLOOKUP(A24,Listados!$A$3:$D$1252,2,FALSE),"") | E24: =IF(NOT(ISBLANK(A24)),VLOOKUP(A24,Listados!$A$3:$D$1252,4,FALSE),"") | F24: =IF(ISERROR(D24),"El código de ciudad no es válido",IF(AND(NOT(ISNUMBER(SUM(B24:C24))),NOT(A24="")),"Escriba la muestra para esta ciudad","")) | G24: =IF(NOT(F24=""),1,0) -> 0 | I24: =_xlfn.CONCAT(IF(AND(NOT(A24=""),ISNUMBER(B24)),"EXEC [dbo].[IQ_InsertarMuestra_WORK] "&A24&", "&B24&", 40, "&$I$8&", "&$I$11&", "&$I$10&", "&$I$9&";",""),IF(AND(NOT(A24=""),ISNUMBER(C24)),"EXEC [dbo].[IQ_InsertarMuestra_WORK] "&A24&", "&C24&", 50, "&$I$8&", "&$I$11&", "&$I$10&", "&$I$9&";",""))
D25: =IF(NOT(ISBLANK(A25)),VLOOKUP(A25,Listados!$A$3:$D$1252,2,FALSE),"") | E25: =IF(NOT(ISBLANK(A25)),VLOOKUP(A25,Listados!$A$3:$D$1252,4,FALSE),"") | F25: =IF(ISERROR(D25),"El código de ciudad no es válido",IF(AND(NOT(ISNUMBER(SUM(B25:C25))),NOT(A25="")),"Escriba la muestra para esta ciudad","")) | G25: =IF(NOT(F25=""),1,0) -> 0 | I25: =_xlfn.CONCAT(IF(AND(NOT(A25=""),ISNUMBER(B25)),"EXEC [dbo].[IQ_InsertarMuestra_WORK] "&A25&", "&B25&", 40, "&$I$8&", "&$I$11&", "&$I$10&", "&$I$9&";",""),IF(AND(NOT(A25=""),ISNUMBER(C25)),"EXEC [dbo].[IQ_InsertarMuestra_WORK] "&A25&", "&C25&", 50, "&$I$8&", "&$I$11&", "&$I$10&", "&$I$9&";",""))
D26: =IF(NOT(ISBLANK(A26)),VLOOKUP(A26,Listados!$A$3:$D$1252,2,FALSE),"") | E26: =IF(NOT(ISBLANK(A26)),VLOOKUP(A26,Listados!$A$3:$D$1252,4,FALSE),"") | F26: =IF(ISERROR(D26),"El código de ciudad no es válido",IF(AND(NOT(ISNUMBER(SUM(B26:C26))),NOT(A26="")),"Escriba la muestra para esta ciudad","")) | G26: =IF(NOT(F26=""),1,0) -> 0 | I26: =_xlfn.CONCAT(IF(AND(NOT(A26=""),ISNUMBER(B26)),"EXEC [dbo].[IQ_InsertarMuestra_WORK] "&A26&", "&B26&", 40, "&$I$8&", "&$I$11&", "&$I$10&", "&$I$9&";",""),IF(AND(NOT(A26=""),ISNUMBER(C26)),"EXEC [dbo].[IQ_InsertarMuestra_WORK] "&A26&", "&C26&", 50, "&$I$8&", "&$I$11&", "&$I$10&", "&$I$9&";",""))
D27: =IF(NOT(ISBLANK(A27)),VLOOKUP(A27,Listados!$A$3:$D$1252,2,FALSE),"") | E27: =IF(NOT(ISBLANK(A27)),VLOOKUP(A27,Listados!$A$3:$D$1252,4,FALSE),"") | F27: =IF(ISERROR(D27),"El código de ciudad no es válido",IF(AND(NOT(ISNUMBER(SUM(B27:C27))),NOT(A27="")),"Escriba la muestra para esta ciudad","")) | G27: =IF(NOT(F27=""),1,0) -> 0 | I27: =_xlfn.CONCAT(IF(AND(NOT(A27=""),ISNUMBER(B27)),"EXEC [dbo].[IQ_InsertarMuestra_WORK] "&A27&", "&B27&", 40, "&$I$8&", "&$I$11&", "&$I$10&", "&$I$9&";",""),IF(AND(NOT(A27=""),ISNUMBER(C27)),"EXEC [dbo].[IQ_InsertarMuestra_WORK] "&A27&", "&C27&", 50, "&$I$8&", "&$I$11&", "&$I$10&", "&$I$9&";",""))
... D264: =IF(NOT(ISBLANK(A264)),VLOOKUP(A264,Listados!$A$3:$D$1252,2,FALSE),"") | E264: =IF(NOT(ISBLANK(A264)),VLOOKUP(A264,Listados!$A$3:$D$1252,4,FALSE),"") | F264: =IF(ISERROR(D264),"El código de ciudad no es válido",IF(AND(NOT(ISNUMBER(SUM(B264:C264))),NOT(A264="")),"Escriba la muestra para esta ciudad","")) | G264: =IF(NOT(F264=""),1,0) -> 0 | I264: =_xlfn.CONCAT(IF(AND(NOT(A264=""),ISNUMBER(B264)),"EXEC [dbo].[IQ_InsertarMuestra_WORK] "&A264&", "&B264&", 40, "&$I$8&", "&$I$11&", "&$I$10&", "&$I$9&";",""),IF(AND(NOT(A264=""),ISNUMBER(C264)),"EXEC [dbo].[IQ_InsertarMuestra_WORK] "&A264&", "&C264&", 50, "&$I$8&", "&$I$11&", "&$I$10&", "&$I$9&";",""))

Sheet Listados
A1: Ciudades | F1: Código | G1: Metodología Estratos
A2: CiuCiudad | B2: CiuNombre | C2: CiuDep | D2: CiuDeptoNombre | F2: 100 | G2: Hogares | H2: 100
A3: 5001 | B3: Medellin | C3: 5 | D3: ANTIOQUIA | F3: 105 | G3: Hogares (Prueba de producto) | H3: 105
A4: 5002 | B4: Abejorral | C4: 5 | D4: ANTIOQUIA | F4: 110 | G4: Interceptacion | H4: 110
A5: 5030 | B5: Amaga | C5: 5 | D5: ANTIOQUIA | F5: 120 | G5: Localizacion central (Prueba de producto) | H5: 120
A6: 5034 | B6: Andes | C6: 5 | D6: ANTIOQUIA | F6: 125 | G6: Localizacion central (Otros) | H6: 125
A7: 5045 | B7: Apartado | C7: 5 | D7: ANTIOQUIA | F7: 150 | G7: Tracking | H7: 150
A8: 5079 | B8: Barbosa | C8: 5 | D8: ANTIOQUIA | F8: 170 | G8: Lista de clientes (Campo presencial) | H8: 170
A9: 5088 | B9: Bello | C9: 5 | D9: ANTIOQUIA
A10: 5091 | B10: Betania | C10: 5 | D10: ANTIOQUIA
A11: 5129 | B11: Caldas | C11: 5 | D11: ANTIOQUIA | F11: Código | G11: Metodología Dificultad
A12: 5145 | B12: Caramanta | C12: 5 | D12: ANTIOQUIA | F12: 130 | G12: Especializada | H12: 130
A13: 5150 | B13: Carolina | C13: 5 | D13: ANTIOQUIA | F13: 140 | G13: Mystery Shopper | H13: 140
A14: 5154 | B14: Caucasia | C14: 5 | D14: ANTIOQUIA | F14: 160 | G14: Muestra cautiva(Autoaplicada) | H14: 160
A15: 5190 | B15: Cisneros | C15: 5 | D15: ANTIOQUIA | F15: 300 | G15: Lista de clientes (Campo online) | H15: 300
A16: 5212 | B16: COPACABANA | C16: 5 | D16: ANTIOQUIA | F16: 310 | G16: Lista de empleados (Campo online) | H16: 310
A17: 5237 | B17: DON MATIAS | C17: 5 | D17: ANTIOQUIA | F17: 320 | G17: Panel | H17: 320
A18: 5282 | B18: FREDONIA | C18: 5 | D18: ANTIOQUIA
A19: 5308 | B19: GIRARDOTA | C19: 5 | D19: ANTIOQUIA
A20: 5310 | B20: GOMEZ PLATA | C20: 5 | D20: ANTIOQUIA | F20: IdFase | G20: DescFase
A21: 5315 | B21: GUADALUPE | C21: 5 | D21: ANTIOQUIA | F21: 1 | G21: Nacional | H21: 1
A22: 5360 | B22: Itagui | C22: 5 | D22: ANTIOQUIA | F22: 2 | G22: Internacional | H22: 2
A23: 5579 | B23: Puerto Berrio | C23: 5 | D23: ANTIOQUIA | F23: 3 | G23: Visita 1 / Segmento 1 / Medicion 1 | H23: 3
A24: 5591 | B24: Puerto Triunfo | C24: 5 | D24: ANTIOQUIA | F24: 4 | G24: Visita 2 / Segmento 2 / Medicion 2 | H24: 4
A25: 5615 | B25: Rionegro | C25: 5 | D25: ANTIOQUIA | F25: 5 | G25: Visita 3 / Segmento 3 / Medicion 3 | H25: 5
A26: 5756 | B26: Sonson | C26: 5 | D26: ANTIOQUIA | F26: 6 | G26: Visita 4 / Segmento 4 / Medicion 4 | H26: 6
A27: 5837 | B27: Turbo | C27: 5 | D27: ANTIOQUIA | F27: 7 | G27: Visita 5 / Segmento 5 / Medicion 5 | H27: 7
A28: 5887 | B28: Yarumal | C28: 5 | D28: ANTIOQUIA | F28: 8 | G28: Visita 6 / Segmento 6 / Medicion 6 | H28: 8
A29: 5995 | B29: MUNICIPIO 7 | C29: 5 | D29: ANTIOQUIA | F29: 9 | G29: Visita 7 / Segmento 7 / Medicion 7 | H29: 9
A30: 5996 | B30: MUNICIPIO 8 | C30: 5 | D30: ANTIOQUIA | F30: 10 | G30: Visita 8 / Segmento 8 / Medicion 8 | H30: 10
A31: 8001 | B31: Barranquilla | C31: 8 | D31: ATLANTICO | F31: 11 | G31: Visita 9 / Segmento 9 / Medicion 9 | H31: 11
A32: 8296 | B32: Galapa | C32: 8 | D32: ATLANTICO | F32: 12 | G32: Visita 10 / Segmento 10 / Medicion 10 | H32: 12
... A37: 8634 | B37: Sabana Grande | C37: 8 | D37: ATLANTICO | F37: 17 | G37: Visita 15 / Segmento 15 / Medicion 15 | H37: 17
A38: 8638 | B38: Sabana Larga | C38: 8 | D38: ATLANTICO
A39: 8675 | B39: Santa Lucia | C39: 8 | D39: ATLANTICO
A40: 8685 | B40: Santo Tomas | C40: 8 | D40: ATLANTICO
A41: 8995 | B41: MUNICIPIO 1 | C41: 8 | D41: ATLANTICO
A42: 8996 | B42: MUNICIPIO 2 | C42: 8 | D42: ATLANTICO
A43: 8997 | B43: MUNICIPIO 3 | C43: 8 | D43: ATLANTICO
A44: 11001 | B44: Bogota | C44: 11 | D44: Distrito Capital
...
